Workbook

Sheet scenario_jobcoeff_4506_iotable_
A1: code | B1: sector name | C1: 2026 | D1: 2027 | E1: 2028 | F1: 2029 | G1: 2030 | H1: 2031 | I1: 2032 | J1: 2033 | K1: 2034 | L1: 2035 | M1: 2036 | N1: 2037 | O1: 2038 | P1: 2039 | Q1: 2040 | R1: 2041 | S1: 2042 | T1: 2043 | U1: 2044 | V1: 2045 | W1: 2046 | X1: 2047 | Y1: 2048 | Z1: 2049 | AA1: 2050
A2: 011 | B2: 곡물 및 식량작물 | C2: 207.83079 | D2: 226.81275 | E2: 235.88526 | F2: 249.93639 | G2: 306.01567 | H2: 318.2563 | I2: 335.35143 | J2: 397.69762 | K2: 413.60553 | L2: 498.28864 | M2: 542.09096 | N2: 581.02597 | O2: 581.02597 | P2: 581.02597 | Q2: 615.09717 | R2: 615.09717 | S2: 653.05101 | T2: 653.05101 | U2: 688.09286 | V2: 688.09286 | W2: 718.2639 | X2: 718.2639 | Y2: 718.2639 | Z2: 718.2639 | AA2: 718.2639
A3: 012 | B3: 채소 및 과실 | C3: 265.14346 | D3: 289.36 | E3: 300.9344 | F3: 318.86035 | G3: 390.4044 | H3: 406.02058 | I3: 427.82996 | J3: 507.36912 | K3: 527.66388 | L3: 635.69972 | M3: 691.58124 | N3: 741.2532 | O3: 741.2532 | P3: 741.2532 | Q3: 784.72008 | R3: 784.72008 | S3: 833.14029 | T3: 833.14029 | U3: 877.8455 | V3: 877.8455 | W3: 916.33669 | X3: 916.33669 | Y3: 916.33669 | Z3: 916.33669 | AA3: 916.33669
A4: 019 | B4: 기타작물 | C4: 59.308082 | D4: 64.72491 | E4: 67.313907 | F4: 71.323637 | G4: 87.326824 | H4: 90.819897 | I4: 95.698285 | J4: 113.48984 | K4: 118.02944 | L4: 142.19522 | M4: 154.69496 | N4: 165.80573 | O4: 165.80573 | P4: 165.80573 | Q4: 175.52853 | R4: 175.52853 | S4: 186.35931 | T4: 186.35931 | U4: 196.35911 | V4: 196.35911 | W4: 204.96893 | X4: 204.96893 | Y4: 204.96893 | Z4: 204.96893 | AA4: 204.96893
A5: 021 | B5: 낙농 및 축우 | C5: 17.251994 | D5: 18.827683 | E5: 19.580791 | F5: 20.747172 | G5: 25.402303 | H5: 26.418395 | I5: 27.837458 | J5: 33.012804 | K5: 34.333317 | L5: 41.362846 | M5: 44.998868 | N5: 48.230856 | O5: 48.230856 | P5: 48.230856 | Q5: 51.0591 | R5: 51.0591 | S5: 54.20964 | T5: 54.20964 | U5: 57.118458 | V5: 57.118458 | W5: 59.622951 | X5: 59.622951 | Y5: 59.622951 | Z5: 59.622951 | AA5: 59.622951
A6: 029 | B6: 기타 축산 | C6: 21.555484 | D6: 23.524226 | E6: 24.465195 | F6: 25.922529 | G6: 31.738877 | H6: 33.008432 | I6: 34.781479 | J6: 41.247809 | K6: 42.897721 | L6: 51.680758 | M6: 56.223781 | N6: 60.261985 | O6: 60.261985 | P6: 60.261985 | Q6: 63.79573 | R6: 63.79573 | S6: 67.73217 | T6: 67.73217 | U6: 71.366589 | V6: 71.366589 | W6: 74.495823 | X6: 74.495823 | Y6: 74.495823 | Z6: 74.495823 | AA6: 74.495823
A7: 030 | B7: 임산물 | C7: 8.2241834 | D7: 8.9753287 | E7: 9.3343419 | F7: 9.8903666 | G7: 12.10951 | H7: 12.59389 | I7: 13.270371 | J7: 15.737506 | K7: 16.367006 | L7: 19.718047 | M7: 21.451372 | N7: 22.99209 | O7: 22.99209 | P7: 22.99209 | Q7: 24.34034 | R7: 24.34034 | S7: 25.842231 | T7: 25.842231 | U7: 27.228891 | V7: 27.228891 | W7: 28.422806 | X7: 28.422806 | Y7: 28.422806 | Z7: 28.422806 | AA7: 28.422806
A8: 040 | B8: 수산물 | C8: 23.073556 | D8: 25.18095 | E8: 26.188188 | F8: 27.748156 | G8: 33.974128 | H8: 35.333093 | I8: 37.231008 | J8: 44.152738 | K8: 45.918847 | L8: 55.320441 | M8: 60.183413 | N8: 64.506011 | O8: 64.506011 | P8: 64.506011 | Q8: 68.288626 | R8: 68.288626 | S8: 72.502294 | T8: 72.502294 | U8: 76.392671 | V8: 76.392671 | W8: 79.742287 | X8: 79.742287 | Y8: 79.742287 | Z8: 79.742287 | AA8: 79.742287
A9: 050 | B9: 농림어업 서비스 | C9: 5.2667393 | D9: 5.7477702 | E9: 5.977681 | F9: 6.3337574 | G9: 7.7548894 | H9: 8.0650849 | I9: 8.4983007 | J9: 10.078245 | K9: 10.481375 | L9: 12.627371 | M9: 13.737386 | N9: 14.724057 | O9: 14.724057 | P9: 14.724057 | Q9: 15.587471 | R9: 15.587471 | S9: 16.549278 | T9: 16.549278 | U9: 17.43729 | V9: 17.43729 | W9: 18.201869 | X9: 18.201869 | Y9: 18.201869 | Z9: 18.201869 | AA9: 18.201869
A10: 061 | B10: 석탄 | C10: 305.92292 | D10: 333.864 | E10: 347.21855 | F10: 367.90155 | G10: 450.44918 | H10: 468.46714 | I10: 493.63084 | J10: 585.40324 | K10: 608.81937 | L10: 733.47128 | M10: 797.94746 | N10: 855.25904 | O10: 855.25904 | P10: 855.25904 | Q10: 905.41118 | R10: 905.41118 | S10: 961.2785 | T10: 961.2785 | U10: 1012.8594 | V10: 1012.8594 | W10: 1057.2706 | X10: 1057.2706 | Y10: 1057.2706 | Z10: 1057.2706 | AA10: 1057.2706
A11: 062 | B11: 원유 및 천연가스 | C11: 34.594181 | D11: 37.753796 | E11: 39.263948 | F11: 41.602808 | G11: 50.937407 | H11: 52.974903 | I11: 55.820448 | J11: 66.198197 | K11: 68.846124 | L11: 82.941933 | M11: 90.232986 | N11: 96.713858 | O11: 96.713858 | P11: 96.713858 | Q11: 102.38513 | R11: 102.38513 | S11: 108.70268 | T11: 108.70268 | U11: 114.53553 | V11: 114.53553 | W11: 119.5576 | X11: 119.5576 | Y11: 119.5576 | Z11: 119.5576 | AA11: 119.5576
A12: 071 | B12: 금속광물 | C12: 0.90186734 | D12: 0.98423824 | E12: 1.0236078 | F12: 1.0845817 | G12: 1.3279339 | H12: 1.3810512 | I12: 1.4552343 | J12: 1.7257813 | K12: 1.7948126 | L12: 2.1622891 | M12: 2.3523663 | N12: 2.521322 | O12: 2.521322 | P12: 2.521322 | Q12: 2.6691716 | R12: 2.6691716 | S12: 2.8338697 | T12: 2.8338697 | U12: 2.9859314 | V12: 2.9859314 | W12: 3.1168565 | X12: 3.1168565 | Y12: 3.1168565 | Z12: 3.1168565 | AA12: 3.1168565
A13: 072 | B13: 비금속광물 | C13: 7.9267034 | D13: 8.6506787 | E13: 8.9967059 | F13: 9.5326185 | G13: 11.671492 | H13: 12.138352 | I13: 12.790363 | J13: 15.168258 | K13: 15.774989 | L13: 19.004818 | M13: 20.675446 | N13: 22.160434 | O13: 22.160434 | P13: 22.160434 | Q13: 23.459916 | R13: 23.459916 | S13: 24.907482 | T13: 24.907482 | U13: 26.243985 | V13: 26.243985 | W13: 27.394714 | X13: 27.394714 | Y13: 27.394714 | Z13: 27.394714 | AA13: 27.394714
... A166: 830 | B166: 기타 | C166: 0 | D166: 0 | E166: 0 | F166: 0 | G166: 0 | H166: 0 | I166: 0 | J166: 0 | K166: 0 | L166: 0 | M166: 0 | N166: 0 | O166: 0 | P166: 0 | Q166: 0 | R166: 0 | S166: 0 | T166: 0 | U166: 0 | V166: 0 | W166: 0 | X166: 0 | Y166: 0 | Z166: 0 | AA166: 0

Sheet scenario_jobcoeff_1610_iotable_
A1: code | B1: sector name | C1: 2026 | D1: 2027 | E1: 2028 | F1: 2029 | G1: 2030 | H1: 2031 | I1: 2032 | J1: 2033 | K1: 2034 | L1: 2035 | M1: 2036 | N1: 2037 | O1: 2038 | P1: 2039 | Q1: 2040 | R1: 2041 | S1: 2042 | T1: 2043 | U1: 2044 | V1: 2045 | W1: 2046 | X1: 2047 | Y1: 2048 | Z1: 2049 | AA1: 2050
A2: 011 | B2: 곡물 및 식량작물 | C2: -52.030227 | D2: -94.996356 | E2: -94.996356 | F2: -112.18281 | G2: -257.86119 | H2: -257.86119 | I2: -257.86119 | J2: -339.12808 | K2: -339.12808 | L2: -442.00227 | M2: -509.52687 | N2: -568.55726 | O2: -568.55726 | P2: -568.55726 | Q2: -620.38044 | R2: -620.38044 | S2: -677.58044 | T2: -677.58044 | U2: -731.97763 | V2: -731.97763 | W2: -778.29532 | X2: -778.29532 | Y2: -778.29532 | Z2: -778.29532 | AA2: -778.29532
A3: 012 | B3: 채소 및 과실 | C3: -53.037135 | D3: -96.834759 | E3: -96.834759 | F3: -114.35381 | G3: -262.85141 | H3: -262.85141 | I3: -262.85141 | J3: -345.69101 | K3: -345.69101 | L3: -450.55606 | M3: -519.38741 | N3: -579.56018 | O3: -579.56018 | P3: -579.56018 | Q3: -632.38626 | R3: -632.38626 | S3: -690.69321 | T3: -690.69321 | U3: -746.14312 | V3: -746.14312 | W3: -793.35717 | X3: -793.35717 | Y3: -793.35717 | Z3: -793.35717 | AA3: -793.35717
A4: 019 | B4: 기타작물 | C4: -12.913125 | D4: -23.576676 | E4: -23.576676 | F4: -27.842097 | G4: -63.997294 | H4: -63.997294 | I4: -63.997294 | J4: -84.166522 | K4: -84.166522 | L4: -109.69836 | M4: -126.45695 | N4: -141.10742 | O4: -141.10742 | P4: -141.10742 | Q4: -153.96916 | R4: -153.96916 | S4: -168.16534 | T4: -168.16534 | U4: -181.66591 | V4: -181.66591 | W4: -193.16127 | X4: -193.16127 | Y4: -193.16127 | Z4: -193.16127 | AA4: -193.16127
A5: 021 | B5: 낙농 및 축우 | C5: -4.2625823 | D5: -7.7825873 | E5: -7.7825873 | F5: -9.1905895 | G5: -21.125307 | H5: -21.125307 | I5: -21.125307 | J5: -27.783107 | K5: -27.783107 | L5: -36.211087 | M5: -41.743047 | N5: -46.579118 | O5: -46.579118 | P5: -46.579118 | Q5: -50.824738 | R5: -50.824738 | S5: -55.510854 | T5: -55.510854 | U5: -59.967351 | V5: -59.967351 | W5: -63.761933 | X5: -63.761933 | Y5: -63.761933 | Z5: -63.761933 | AA5: -63.761933
A6: 029 | B6: 기타 축산 | C6: -5.4280088 | D6: -9.9104133 | E6: -9.9104133 | F6: -11.703375 | G6: -26.901147 | H6: -26.901147 | I6: -26.901147 | J6: -35.379246 | K6: -35.379246 | L6: -46.111508 | M6: -53.155953 | N6: -59.314248 | O6: -59.314248 | P6: -59.314248 | Q6: -64.720657 | R6: -64.720657 | S6: -70.687997 | T6: -70.687997 | U6: -76.362938 | V6: -76.362938 | W6: -81.194991 | X6: -81.194991 | Y6: -81.194991 | Z6: -81.194991 | AA6: -81.194991
A7: 030 | B7: 임산물 | C7: -0.87352149 | D7: -1.5948683 | E7: -1.5948683 | F7: -1.883407 | G7: -4.3291621 | H7: -4.3291621 | I7: -4.3291621 | J7: -5.6935301 | K7: -5.6935301 | L7: -7.4206572 | M7: -8.5543095 | N7: -9.5453548 | O7: -9.5453548 | P7: -9.5453548 | Q7: -10.4154 | R7: -10.4154 | S7: -11.375716 | T7: -11.375716 | U7: -12.288976 | V7: -12.288976 | W7: -13.066591 | X7: -13.066591 | Y7: -13.066591 | Z7: -13.066591 | AA7: -13.066591
A8: 040 | B8: 수산물 | C8: -5.9928056 | D8: -10.941615 | E8: -10.941615 | F8: -12.921138 | G8: -29.700274 | H8: -29.700274 | I8: -29.700274 | J8: -39.060538 | K8: -39.060538 | L8: -50.909516 | M8: -58.686952 | N8: -65.486032 | O8: -65.486032 | P8: -65.486032 | Q8: -71.454991 | R8: -71.454991 | S8: -78.043246 | T8: -78.043246 | U8: -84.308678 | V8: -84.308678 | W8: -89.643517 | X8: -89.643517 | Y8: -89.643517 | Z8: -89.643517 | AA8: -89.643517
A9: 050 | B9: 농림어업 서비스 | C9: -1.0932923 | D9: -1.996124 | E9: -1.996124 | F9: -2.3572567 | G9: -5.4183438 | H9: -5.4183438 | I9: -5.4183438 | J9: -7.1259756 | K9: -7.1259756 | L9: -9.2876337 | M9: -10.706504 | N9: -11.946888 | O9: -11.946888 | P9: -11.946888 | Q9: -13.03583 | R9: -13.03583 | S9: -14.237752 | T9: -14.237752 | U9: -15.380781 | V9: -15.380781 | W9: -16.354038 | X9: -16.354038 | Y9: -16.354038 | Z9: -16.354038 | AA9: -16.354038
A10: 061 | B10: 석탄 | C10: -435.91012 | D10: -795.88108 | E10: -795.88108 | F10: -939.86947 | G10: -2160.3654 | H10: -2160.3654 | I10: -2160.3654 | J10: -2841.2208 | K10: -2841.2208 | L10: -3703.1025 | M10: -4268.8247 | N10: -4763.3823 | O10: -4763.3823 | P10: -4763.3823 | Q10: -5197.5578 | R10: -5197.5578 | S10: -5676.7803 | T10: -5676.7803 | U10: -6132.521 | V10: -6132.521 | W10: -6520.5714 | X10: -6520.5714 | Y10: -6520.5714 | Z10: -6520.5714 | AA10: -6520.5714
A11: 062 | B11: 원유 및 천연가스 | C11: -0.26143496 | D11: -0.47732577 | E11: -0.47732577 | F11: -0.5636821 | G11: -1.2956685 | H11: -1.2956685 | I11: -1.2956685 | J11: -1.7040082 | K11: -1.7040082 | L11: -2.2209175 | M11: -2.5602067 | N11: -2.8568152 | O11: -2.8568152 | P11: -2.8568152 | Q11: -3.1172098 | R11: -3.1172098 | S11: -3.4046211 | T11: -3.4046211 | U11: -3.6779493 | V11: -3.6779493 | W11: -3.9106807 | X11: -3.9106807 | Y11: -3.9106807 | Z11: -3.9106807 | AA11: -3.9106807
A12: 071 | B12: 금속광물 | C12: -0.11767903 | D12: -0.2148574 | E12: -0.2148574 | F12: -0.25372874 | G12: -0.58321588 | H12: -0.58321588 | I12: -0.58321588 | J12: -0.76702075 | K12: -0.76702075 | L12: -0.99969579 | M12: -1.1524191 | N12: -1.2859307 | O12: -1.2859307 | P12: -1.2859307 | Q12: -1.4031415 | R12: -1.4031415 | S12: -1.5325132 | T12: -1.5325132 | U12: -1.6555457 | V12: -1.6555457 | W12: -1.7603044 | X12: -1.7603044 | Y12: -1.7603044 | Z12: -1.7603044 | AA12: -1.7603044
A13: 072 | B13: 비금속광물 | C13: -1.1124365 | D13: -2.0310773 | E13: -2.0310773 | F13: -2.3985336 | G13: -5.513222 | H13: -5.513222 | I13: -5.513222 | J13: -7.2507554 | K13: -7.2507554 | L13: -9.4502654 | M13: -10.89398 | N13: -12.156084 | O13: -12.156084 | P13: -12.156084 | Q13: -13.264094 | R13: -13.264094 | S13: -14.487063 | T13: -14.487063 | U13: -15.650107 | V13: -15.650107 | W13: -16.640406 | X13: -16.640406 | Y13: -16.640406 | Z13: -16.640406 | AA13: -16.640406
... A166: 830 | B166: 기타 | C166: 0 | D166: 0 | E166: 0 | F166: 0 | G166: 0 | H166: 0 | I166: 0 | J166: 0 | K166: 0 | L166: 0 | M166: 0 | N166: 0 | O166: 0 | P166: 0 | Q166: 0 | R166: 0 | S166: 0 | T166: 0 | U166: 0 | V166: 0 | W166: 0 | X166: 0 | Y166: 0 | Z166: 0 | AA166: 0

Sheet scenario_indirect_prod_4506_iot
A1: Column1 | B1: Column2 | C1: 2026 | D1: 2027 | E1: 2028 | F1: 2029 | G1: 2030 | H1: 2031 | I1: 2032 | J1: 2033 | K1: 2034 | L1: 2035 | M1: 2036 | N1: 2037 | O1: 2038 | P1: 2039 | Q1: 2040 | R1: 2041 | S1: 2042 | T1: 2043 | U1: 2044 | V1: 2045 | W1: 2046 | X1: 2047 | Y1: 2048 | Z1: 2049 | AA1: 2050
A2: 0111 | B2: 벼 | C2: 9008.6703 | D2: 9831.4656 | E2: 10224.724 | F2: 10833.787 | G2: 13264.61 | H2: 13795.194 | I2: 14536.202 | J2: 17238.672 | K2: 17928.219 | L2: 21598.908 | M2: 23497.571 | N2: 25185.255 | O2: 25185.255 | P2: 25185.255 | Q2: 26662.111 | R2: 26662.111 | S2: 28307.265 | T2: 28307.265 | U2: 29826.195 | V2: 29826.195 | W2: 31133.995 | X2: 31133.995 | Y2: 31133.995 | Z2: 31133.995 | AA2: 31133.995
A3: 0112 | B3: 맥류 및 잡곡 | C3: 916.45462 | D3: 1000.1578 | E3: 1040.1641 | F3: 1102.1243 | G3: 1349.4126 | H3: 1403.3891 | I3: 1478.7721 | J3: 1753.695 | K3: 1823.8428 | L3: 2197.2631 | M3: 2390.4147 | N3: 2562.1032 | O3: 2562.1032 | P3: 2562.1032 | Q3: 2712.3442 | R3: 2712.3442 | S3: 2879.7062 | T3: 2879.7062 | U3: 3034.2275 | V3: 3034.2275 | W3: 3167.2702 | X3: 3167.2702 | Y3: 3167.2702 | Z3: 3167.2702 | AA3: 3167.2702
A4: 0113 | B4: 콩류 | C4: 22569.595 | D4: 24630.961 | E4: 25616.199 | F4: 27142.096 | G4: 33232.083 | H4: 34561.366 | I4: 36417.828 | J4: 43188.377 | K4: 44915.912 | L4: 54112.161 | M4: 58868.918 | N4: 63097.105 | O4: 63097.105 | P4: 63097.105 | Q4: 66797.101 | R4: 66797.101 | S4: 70918.737 | T4: 70918.737 | U4: 74724.143 | V4: 74724.143 | W4: 78000.597 | X4: 78000.597 | Y4: 78000.597 | Z4: 78000.597 | AA4: 78000.597
A5: 0114 | B5: 감자류 | C5: 1003.9705 | D5: 1095.6668 | E5: 1139.4935 | F5: 1207.3704 | G5: 1478.2733 | H5: 1537.4042 | I5: 1619.9858 | J5: 1921.1623 | K5: 1998.0087 | L5: 2407.0884 | M5: 2618.6847 | N5: 2806.7685 | O5: 2806.7685 | P5: 2806.7685 | Q5: 2971.3566 | R5: 2971.3566 | S5: 3154.7006 | T5: 3154.7006 | U5: 3323.9777 | V5: 3323.9777 | W5: 3469.7253 | X5: 3469.7253 | Y5: 3469.7253 | Z5: 3469.7253 | AA5: 3469.7253
A6: 0121 | B6: 채소 | C6: 8012.5406 | D6: 8744.3558 | E6: 9094.13 | F6: 9635.8459 | G6: 11797.882 | H6: 12269.797 | I6: 12928.868 | J6: 15332.513 | K6: 15945.814 | L6: 19210.619 | M6: 20899.338 | N6: 22400.407 | O6: 22400.407 | P6: 22400.407 | Q6: 23713.96 | R6: 23713.96 | S6: 25177.202 | T6: 25177.202 | U6: 26528.177 | V6: 26528.177 | W6: 27691.367 | X6: 27691.367 | Y6: 27691.367 | Z6: 27691.367 | AA6: 27691.367
A7: 0122 | B7: 과실 | C7: 3158.1169 | D7: 3446.5595 | E7: 3584.4219 | F7: 3797.9374 | G7: 4650.0967 | H7: 4836.1006 | I7: 5095.8716 | J7: 6043.2605 | K7: 6284.9909 | L7: 7571.803 | M7: 8237.4063 | N7: 8829.0477 | O7: 8829.0477 | P7: 8829.0477 | Q7: 9346.7806 | R7: 9346.7806 | S7: 9923.5125 | T7: 9923.5125 | U7: 10455.995 | V7: 10455.995 | W7: 10914.463 | X7: 10914.463 | Y7: 10914.463 | Z7: 10914.463 | AA7: 10914.463
A8: 0191 | B8: 화훼작물 | C8: 760.89337 | D8: 830.38859 | E8: 863.60414 | F8: 915.047 | G8: 1120.36 | H8: 1165.1744 | I8: 1227.7617 | J8: 1456.0186 | K8: 1514.2593 | L8: 1824.2943 | M8: 1984.6598 | N8: 2127.2056 | O8: 2127.2056 | P8: 2127.2056 | Q8: 2251.9443 | R8: 2251.9443 | S8: 2390.8978 | T8: 2390.8978 | U8: 2519.1903 | V8: 2519.1903 | W8: 2629.65 | X8: 2629.65 | Y8: 2629.65 | Z8: 2629.65 | AA8: 2629.65
A9: 0192 | B9: 약용작물 | C9: 453.23695 | D9: 494.63277 | E9: 514.41808 | F9: 545.06075 | G9: 667.35834 | H9: 694.05267 | I9: 731.33369 | J9: 867.29815 | K9: 901.99007 | L9: 1086.6668 | M9: 1182.1908 | N9: 1267.1002 | O9: 1267.1002 | P9: 1267.1002 | Q9: 1341.4026 | R9: 1341.4026 | S9: 1424.1723 | T9: 1424.1723 | U9: 1500.5915 | V9: 1500.5915 | W9: 1566.3884 | X9: 1566.3884 | Y9: 1566.3884 | Z9: 1566.3884 | AA9: 1566.3884
A10: 0193 | B10: 잎담배 | C10: 0 | D10: 0 | E10: 0 | F10: 0 | G10: 0 | H10: 0 | I10: 0 | J10: 0 | K10: 0 | L10: 0 | M10: 0 | N10: 0 | O10: 0 | P10: 0 | Q10: 0 | R10: 0 | S10: 0 | T10: 0 | U10: 0 | V10: 0 | W10: 0 | X10: 0 | Y10: 0 | Z10: 0 | AA10: 0
A11: 0194 | B11: 천연고무 | C11: 0 | D11: 0 | E11: 0 | F11: 0 | G11: 0 | H11: 0 | I11: 0 | J11: 0 | K11: 0 | L11: 0 | M11: 0 | N11: 0 | O11: 0 | P11: 0 | Q11: 0 | R11: 0 | S11: 0 | T11: 0 | U11: 0 | V11: 0 | W11: 0 | X11: 0 | Y11: 0 | Z11: 0 | AA11: 0
A12: 0195 | B12: 종자 | C12: 282.7825 | D12: 308.61007 | E12: 320.95448 | F12: 340.07298 | G12: 416.3766 | H12: 433.03166 | I12: 456.29194 | J12: 541.12255 | K12: 562.76746 | L12: 677.99053 | M12: 737.58964 | N12: 790.5661 | O12: 790.5661 | P12: 790.5661 | Q12: 836.92467 | R12: 836.92467 | S12: 888.5661 | T12: 888.5661 | U12: 936.24539 | V12: 936.24539 | W12: 977.29726 | X12: 977.29726 | Y12: 977.29726 | Z12: 977.29726 | AA12: 977.29726
A13: 0196 | B13: 기타식용작물 | C13: 9261.8825 | D13: 10107.805 | E13: 10512.117 | F13: 11138.299 | G13: 13637.446 | H13: 14182.944 | I13: 14944.78 | J13: 17723.21 | K13: 18432.138 | L13: 22206.002 | M13: 24158.032 | N13: 25893.152 | O13: 25893.152 | P13: 25893.152 | Q13: 27411.519 | R13: 27411.519 | S13: 29102.915 | T13: 29102.915 | U13: 30664.539 | V13: 30664.539 | W13: 32009.097 | X13: 32009.097 | Y13: 32009.097 | Z13: 32009.097 | AA13: 32009.097
... A382: Sector Code | B382: Sector Name | C382: 2026 | D382: 2027 | E382: 2028 | F382: 2029 | G382: 2030 | H382: 2031 | I382: 2032 | J382: 2033 | K382: 2034 | L382: 2035 | M382: 2036 | N382: 2037 | O382: 2038 | P382: 2039 | Q382: 2040 | R382: 2041 | S382: 2042 | T382: 2043 | U382: 2044 | V382: 2045 | W382: 2046 | X382: 2047 | Y382: 2048 | Z382: 2049 | AA382: 2050

Sheet scenario_indirect_prod_1610_iot
A1: Column1 | B1: Column2 | C1: 2026 | D1: 2027 | E1: 2028 | F1: 2029 | G1: 2030 | H1: 2031 | I1: 2032 | J1: 2033 | K1: 2034 | L1: 2035 | M1: 2036 | N1: 2037 | O1: 2038 | P1: 2039 | Q1: 2040 | R1: 2041 | S1: 2042 | T1: 2043 | U1: 2044 | V1: 2045 | W1: 2046 | X1: 2047 | Y1: 2048 | Z1: 2049 | AA1: 2050
A2: 0111 | B2: 벼 | C2: -1009.8946 | D2: -1843.8571 | E2: -1843.8571 | F2: -2177.4421 | G2: -5005.0255 | H2: -5005.0255 | I2: -5005.0255 | J2: -6582.3969 | K2: -6582.3969 | L2: -8579.1609 | M2: -9889.7975 | N2: -11035.564 | O2: -11035.564 | P2: -11035.564 | Q2: -12041.44 | R2: -12041.44 | S2: -13151.678 | T2: -13151.678 | U2: -14207.515 | V2: -14207.515 | W2: -15106.53 | X2: -15106.53 | Y2: -15106.53 | Z2: -15106.53 | AA2: -15106.53
A3: 0112 | B3: 맥류 및 잡곡 | C3: -41.444313 | D3: -75.668681 | E3: -75.668681 | F3: -89.35843 | G3: -205.39752 | H3: -205.39752 | I3: -205.39752 | J3: -270.1301 | K3: -270.1301 | L3: -352.07381 | M3: -405.86005 | N3: -452.8803 | O3: -452.8803 | P3: -452.8803 | Q3: -494.15969 | R3: -494.15969 | S3: -539.72194 | T3: -539.72194 | U3: -583.05165 | V3: -583.05165 | W3: -619.94568 | X3: -619.94568 | Y3: -619.94568 | Z3: -619.94568 | AA3: -619.94568
A4: 0113 | B4: 콩류 | C4: -35.523048 | D4: -64.857685 | E4: -64.857685 | F4: -76.591541 | G4: -176.0518 | H4: -176.0518 | I4: -176.0518 | J4: -231.53585 | K4: -231.53585 | L4: -301.77204 | M4: -347.87369 | N4: -388.17602 | O4: -388.17602 | P4: -388.17602 | Q4: -423.55771 | R4: -423.55771 | S4: -462.61036 | T4: -462.61036 | U4: -499.74943 | V4: -499.74943 | W4: -531.37231 | X4: -531.37231 | Y4: -531.37231 | Z4: -531.37231 | AA4: -531.37231
A5: 0114 | B5: 감자류 | C5: -109.5278 | D5: -199.97495 | E5: -199.97495 | F5: -236.15382 | G5: -542.81849 | H5: -542.81849 | I5: -542.81849 | J5: -713.89183 | K5: -713.89183 | L5: -930.45025 | M5: -1072.5949 | N5: -1196.8586 | O5: -1196.8586 | P5: -1196.8586 | Q5: -1305.9506 | R5: -1305.9506 | S5: -1426.3612 | T5: -1426.3612 | U5: -1540.8717 | V5: -1540.8717 | W5: -1638.3741 | X5: -1638.3741 | Y5: -1638.3741 | Z5: -1638.3741 | AA5: -1638.3741
A6: 0121 | B6: 채소 | C6: -1048.9663 | D6: -1915.1939 | E6: -1915.1939 | F6: -2261.685 | G6: -5198.6645 | H6: -5198.6645 | I6: -5198.6645 | J6: -6837.0627 | K6: -6837.0627 | L6: -8911.0794 | M6: -10272.423 | N6: -11462.518 | O6: -11462.518 | P6: -11462.518 | Q6: -12507.31 | R6: -12507.31 | S6: -13660.502 | T6: -13660.502 | U6: -14757.188 | V6: -14757.188 | W6: -15690.986 | X6: -15690.986 | Y6: -15690.986 | Z6: -15690.986 | AA6: -15690.986
A7: 0122 | B7: 과실 | C7: -520.90913 | D7: -951.07156 | E7: -951.07156 | F7: -1123.1366 | G7: -2581.6195 | H7: -2581.6195 | I7: -2581.6195 | J7: -3395.2363 | K7: -3395.2363 | L7: -4425.1781 | M7: -5101.2116 | N7: -5692.204 | O7: -5692.204 | P7: -5692.204 | Q7: -6211.0403 | R7: -6211.0403 | S7: -6783.7074 | T7: -6783.7074 | U7: -7328.3138 | V7: -7328.3138 | W7: -7792.031 | X7: -7792.031 | Y7: -7792.031 | Z7: -7792.031 | AA7: -7792.031
A8: 0191 | B8: 화훼작물 | C8: -111.16049 | D8: -202.9559 | E8: -202.9559 | F8: -239.67406 | G8: -550.91007 | H8: -550.91007 | I8: -550.91007 | J8: -724.53352 | K8: -724.53352 | L8: -944.32009 | M8: -1088.5837 | N8: -1214.6997 | O8: -1214.6997 | P8: -1214.6997 | Q8: -1325.4179 | R8: -1325.4179 | S8: -1447.6234 | T8: -1447.6234 | U8: -1563.8408 | V8: -1563.8408 | W8: -1662.7967 | X8: -1662.7967 | Y8: -1662.7967 | Z8: -1662.7967 | AA8: -1662.7967
A9: 0192 | B9: 약용작물 | C9: -84.744265 | D9: -154.72537 | E9: -154.72537 | F9: -182.71782 | G9: -419.99157 | H9: -419.99157 | I9: -419.99157 | J9: -552.35507 | K9: -552.35507 | L9: -719.91148 | M9: -829.8922 | N9: -926.03799 | O9: -926.03799 | P9: -926.03799 | Q9: -1010.445 | R9: -1010.445 | S9: -1103.6096 | T9: -1103.6096 | U9: -1192.209 | V9: -1192.209 | W9: -1267.649 | X9: -1267.649 | Y9: -1267.649 | Z9: -1267.649 | AA9: -1267.649
A10: 0193 | B10: 잎담배 | C10: 0 | D10: 0 | E10: 0 | F10: 0 | G10: 0 | H10: 0 | I10: 0 | J10: 0 | K10: 0 | L10: 0 | M10: 0 | N10: 0 | O10: 0 | P10: 0 | Q10: 0 | R10: 0 | S10: 0 | T10: 0 | U10: 0 | V10: 0 | W10: 0 | X10: 0 | Y10: 0 | Z10: 0 | AA10: 0
A11: 0194 | B11: 천연고무 | C11: 0 | D11: 0 | E11: 0 | F11: 0 | G11: 0 | H11: 0 | I11: 0 | J11: 0 | K11: 0 | L11: 0 | M11: 0 | N11: 0 | O11: 0 | P11: 0 | Q11: 0 | R11: 0 | S11: 0 | T11: 0 | U11: 0 | V11: 0 | W11: 0 | X11: 0 | Y11: 0 | Z11: 0 | AA11: 0
A12: 0195 | B12: 종자 | C12: -37.846939 | D12: -69.100627 | E12: -69.100627 | F12: -81.602103 | G12: -187.56898 | H12: -187.56898 | I12: -187.56898 | J12: -246.68276 | K12: -246.68276 | L12: -321.51374 | M12: -370.63133 | N12: -413.57021 | O12: -413.57021 | P12: -413.57021 | Q12: -451.26655 | R12: -451.26655 | S12: -492.87399 | T12: -492.87399 | U12: -532.44267 | V12: -532.44267 | W12: -566.13429 | X12: -566.13429 | Y12: -566.13429 | Z12: -566.13429 | AA12: -566.13429
A13: 0196 | B13: 기타식용작물 | C13: -55.267331 | D13: -100.90663 | E13: -100.90663 | F13: -119.16236 | G13: -273.90424 | H13: -273.90424 | I13: -273.90424 | J13: -360.22722 | K13: -360.22722 | L13: -469.50181 | M13: -541.2275 | N13: -603.93052 | O13: -603.93052 | P13: -603.93052 | Q13: -658.97793 | R13: -658.97793 | S13: -719.73667 | T13: -719.73667 | U13: -777.51823 | V13: -777.51823 | W13: -826.71761 | X13: -826.71761 | Y13: -826.71761 | Z13: -826.71761 | AA13: -826.71761
... A382: Sector Code | B382: Sector Name | C382: 2026 | D382: 2027 | E382: 2028 | F382: 2029 | G382: 2030 | H382: 2031 | I382: 2032 | J382: 2033 | K382: 2034 | L382: 2035 | M382: 2036 | N382: 2037 | O382: 2038 | P382: 2039 | Q382: 2040 | R382: 2041 | S382: 2042 | T382: 2043 | U382: 2044 | V382: 2045 | W382: 2046 | X382: 2047 | Y382: 2048 | Z382: 2049 | AA382: 2050

Sheet total_production
A1: code | B1: sector name | C1: 2026 | D1: 2027 | E1: 2028 | F1: 2029 | G1: 2030 | H1: 2031 | I1: 2032 | J1: 2033 | K1: 2034 | L1: 2035 | M1: 2036 | N1: 2037 | O1: 2038 | P1: 2039 | Q1: 2040 | R1: 2041 | S1: 2042 | T1: 2043 | U1: 2044 | V1: 2045 | W1: 2046 | X1: 2047 | Y1: 2048 | Z1: 2049 | AA1: 2050
A2: 0111 | B2: 벼 | C2: =scenario_indirect_prod_4506_iotable_2020_xlsx_3[[#This Row],[2026]]+scenario_indirect_prod_1610_iotable_2020_xlsx_3[[#This Row],[2026]] -> 7998.7757 | D2: =scenario_indirect_prod_4506_iotable_2020_xlsx_3[[#This Row],[2027]]+scenario_indirect_prod_1610_iotable_2020_xlsx_3[[#This Row],[2027]] -> 7987.6086 | E2: =scenario_indirect_prod_4506_iotable_2020_xlsx_3[[#This Row],[2028]]+scenario_indirect_prod_1610_iotable_2020_xlsx_3[[#This Row],[2028]] -> 8380.8672 | F2: =scenario_indirect_prod_4506_iotable_2020_xlsx_3[[#This Row],[2029]]+scenario_indirect_prod_1610_iotable_2020_xlsx_3[[#This Row],[2029]] -> 8656.3449 | G2: =scenario_indirect_prod_4506_iotable_2020_xlsx_3[[#This Row],[2030]]+scenario_indirect_prod_1610_iotable_2020_xlsx_3[[#This Row],[2030]] -> 8259.5843 | H2: =scenario_indirect_prod_4506_iotable_2020_xlsx_3[[#This Row],[2031]]+scenario_indirect_prod_1610_iotable_2020_xlsx_3[[#This Row],[2031]] -> 8790.1686 | I2: =scenario_indirect_prod_4506_iotable_2020_xlsx_3[[#This Row],[2032]]+scenario_indirect_prod_1610_iotable_2020_xlsx_3[[#This Row],[2032]] -> 9531.177 | J2: =scenario_indirect_prod_4506_iotable_2020_xlsx_3[[#This Row],[2033]]+scenario_indirect_prod_1610_iotable_2020_xlsx_3[[#This Row],[2033]] -> 10656.275 | K2: =scenario_indirect_prod_4506_iotable_2020_xlsx_3[[#This Row],[2034]]+scenario_indirect_prod_1610_iotable_2020_xlsx_3[[#This Row],[2034]] -> 11345.822 | L2: =scenario_indirect_prod_4506_iotable_2020_xlsx_3[[#This Row],[2035]]+scenario_indirect_prod_1610_iotable_2020_xlsx_3[[#This Row],[2035]] -> 13019.747 | M2: =scenario_indirect_prod_4506_iotable_2020_xlsx_3[[#This Row],[2036]]+scenario_indirect_prod_1610_iotable_2020_xlsx_3[[#This Row],[2036]] -> 13607.774 | N2: =scenario_indirect_prod_4506_iotable_2020_xlsx_3[[#This Row],[2037]]+scenario_indirect_prod_1610_iotable_2020_xlsx_3[[#This Row],[2037]] -> 14149.691 | O2: =scenario_indirect_prod_4506_iotable_2020_xlsx_3[[#This Row],[2038]]+scenario_indirect_prod_1610_iotable_2020_xlsx_3[[#This Row],[2038]] -> 14149.691 | P2: =scenario_indirect_prod_4506_iotable_2020_xlsx_3[[#This Row],[2039]]+scenario_indirect_prod_1610_iotable_2020_xlsx_3[[#This Row],[2039]] -> 14149.691 | Q2: =scenario_indirect_prod_4506_iotable_2020_xlsx_3[[#This Row],[2040]]+scenario_indirect_prod_1610_iotable_2020_xlsx_3[[#This Row],[2040]] -> 14620.672 | R2: =scenario_indirect_prod_4506_iotable_2020_xlsx_3[[#This Row],[2041]]+scenario_indirect_prod_1610_iotable_2020_xlsx_3[[#This Row],[2041]] -> 14620.672 | S2: =scenario_indirect_prod_4506_iotable_2020_xlsx_3[[#This Row],[2042]]+scenario_indirect_prod_1610_iotable_2020_xlsx_3[[#This Row],[2042]] -> 15155.587 | T2: =scenario_indirect_prod_4506_iotable_2020_xlsx_3[[#This Row],[2043]]+scenario_indirect_prod_1610_iotable_2020_xlsx_3[[#This Row],[2043]] -> 15155.587 | U2: =scenario_indirect_prod_4506_iotable_2020_xlsx_3[[#This Row],[2044]]+scenario_indirect_prod_1610_iotable_2020_xlsx_3[[#This Row],[2044]] -> 15618.681 | V2: =scenario_indirect_prod_4506_iotable_2020_xlsx_3[[#This Row],[2045]]+scenario_indirect_prod_1610_iotable_2020_xlsx_3[[#This Row],[2045]] -> 15618.681 | W2: =scenario_indirect_prod_4506_iotable_2020_xlsx_3[[#This Row],[2046]]+scenario_indirect_prod_1610_iotable_2020_xlsx_3[[#This Row],[2046]] -> 16027.464 | X2: =scenario_indirect_prod_4506_iotable_2020_xlsx_3[[#This Row],[2047]]+scenario_indirect_prod_1610_iotable_2020_xlsx_3[[#This Row],[2047]] -> 16027.464 | Y2: =scenario_indirect_prod_4506_iotable_2020_xlsx_3[[#This Row],[2048]]+scenario_indirect_prod_1610_iotable_2020_xlsx_3[[#This Row],[2048]] -> 16027.464 | Z2: =scenario_indirect_prod_4506_iotable_2020_xlsx_3[[#This Row],[2049]]+scenario_indirect_prod_1610_iotable_2020_xlsx_3[[#This Row],[2049]] -> 16027.464 | AA2: =scenario_indirect_prod_4506_iotable_2020_xlsx_3[[#This Row],[2050]]+scenario_indirect_prod_1610_iotable_2020_xlsx_3[[#This Row],[2050]] -> 16027.464
A3: 0112 | B3: 맥류 및 잡곡 | C3: =scenario_indirect_prod_4506_iotable_2020_xlsx_3[[#This Row],[2026]]+scenario_indirect_prod_1610_iotable_2020_xlsx_3[[#This Row],[2026]] -> 875.01031 | D3: =scenario_indirect_prod_4506_iotable_2020_xlsx_3[[#This Row],[2027]]+scenario_indirect_prod_1610_iotable_2020_xlsx_3[[#This Row],[2027]] -> 924.48915 | E3: =scenario_indirect_prod_4506_iotable_2020_xlsx_3[[#This Row],[2028]]+scenario_indirect_prod_1610_iotable_2020_xlsx_3[[#This Row],[2028]] -> 964.49546 | F3: =scenario_indirect_prod_4506_iotable_2020_xlsx_3[[#This Row],[2029]]+scenario_indirect_prod_1610_iotable_2020_xlsx_3[[#This Row],[2029]] -> 1012.7658 | G3: =scenario_indirect_prod_4506_iotable_2020_xlsx_3[[#This Row],[2030]]+scenario_indirect_prod_1610_iotable_2020_xlsx_3[[#This Row],[2030]] -> 1144.015 | H3: =scenario_indirect_prod_4506_iotable_2020_xlsx_3[[#This Row],[2031]]+scenario_indirect_prod_1610_iotable_2020_xlsx_3[[#This Row],[2031]] -> 1197.9915 | I3: =scenario_indirect_prod_4506_iotable_2020_xlsx_3[[#This Row],[2032]]+scenario_indirect_prod_1610_iotable_2020_xlsx_3[[#This Row],[2032]] -> 1273.3745 | J3: =scenario_indirect_prod_4506_iotable_2020_xlsx_3[[#This Row],[2033]]+scenario_indirect_prod_1610_iotable_2020_xlsx_3[[#This Row],[2033]] -> 1483.565 | K3: =scenario_indirect_prod_4506_iotable_2020_xlsx_3[[#This Row],[2034]]+scenario_indirect_prod_1610_iotable_2020_xlsx_3[[#This Row],[2034]] -> 1553.7128 | L3: =scenario_indirect_prod_4506_iotable_2020_xlsx_3[[#This Row],[2035]]+scenario_indirect_prod_1610_iotable_2020_xlsx_3[[#This Row],[2035]] -> 1845.1893 | M3: =scenario_indirect_prod_4506_iotable_2020_xlsx_3[[#This Row],[2036]]+scenario_indirect_prod_1610_iotable_2020_xlsx_3[[#This Row],[2036]] -> 1984.5546 | N3: =scenario_indirect_prod_4506_iotable_2020_xlsx_3[[#This Row],[2037]]+scenario_indirect_prod_1610_iotable_2020_xlsx_3[[#This Row],[2037]] -> 2109.2229 | O3: =scenario_indirect_prod_4506_iotable_2020_xlsx_3[[#This Row],[2038]]+scenario_indirect_prod_1610_iotable_2020_xlsx_3[[#This Row],[2038]] -> 2109.2229 | P3: =scenario_indirect_prod_4506_iotable_2020_xlsx_3[[#This Row],[2039]]+scenario_indirect_prod_1610_iotable_2020_xlsx_3[[#This Row],[2039]] -> 2109.2229 | Q3: =scenario_indirect_prod_4506_iotable_2020_xlsx_3[[#This Row],[2040]]+scenario_indirect_prod_1610_iotable_2020_xlsx_3[[#This Row],[2040]] -> 2218.1846 | R3: =scenario_indirect_prod_4506_iotable_2020_xlsx_3[[#This Row],[2041]]+scenario_indirect_prod_1610_iotable_2020_xlsx_3[[#This Row],[2041]] -> 2218.1846 | S3: =scenario_indirect_prod_4506_iotable_2020_xlsx_3[[#This Row],[2042]]+scenario_indirect_prod_1610_iotable_2020_xlsx_3[[#This Row],[2042]] -> 2339.9843 | T3: =scenario_indirect_prod_4506_iotable_2020_xlsx_3[[#This Row],[2043]]+scenario_indirect_prod_1610_iotable_2020_xlsx_3[[#This Row],[2043]] -> 2339.9843 | U3: =scenario_indirect_prod_4506_iotable_2020_xlsx_3[[#This Row],[2044]]+scenario_indirect_prod_1610_iotable_2020_xlsx_3[[#This Row],[2044]] -> 2451.1758 | V3: =scenario_indirect_prod_4506_iotable_2020_xlsx_3[[#This Row],[2045]]+scenario_indirect_prod_1610_iotable_2020_xlsx_3[[#This Row],[2045]] -> 2451.1758 | W3: =scenario_indirect_prod_4506_iotable_2020_xlsx_3[[#This Row],[2046]]+scenario_indirect_prod_1610_iotable_2020_xlsx_3[[#This Row],[2046]] -> 2547.3246 | X3: =scenario_indirect_prod_4506_iotable_2020_xlsx_3[[#This Row],[2047]]+scenario_indirect_prod_1610_iotable_2020_xlsx_3[[#This Row],[2047]] -> 2547.3246 | Y3: =scenario_indirect_prod_4506_iotable_2020_xlsx_3[[#This Row],[2048]]+scenario_indirect_prod_1610_iotable_2020_xlsx_3[[#This Row],[2048]] -> 2547.3246 | Z3: =scenario_indirect_prod_4506_iotable_2020_xlsx_3[[#This Row],[2049]]+scenario_indirect_prod_1610_iotable_2020_xlsx_3[[#This Row],[2049]] -> 2547.3246 | AA3: =scenario_indirect_prod_4506_iotable_2020_xlsx_3[[#This Row],[2050]]+scenario_indirect_prod_1610_iotable_2020_xlsx_3[[#This Row],[2050]] -> 2547.3246
A4: 0113 | B4: 콩류 | C4: =scenario_indirect_prod_4506_iotable_2020_xlsx_3[[#This Row],[2026]]+scenario_indirect_prod_1610_iotable_2020_xlsx_3[[#This Row],[2026]] -> 22534.072 | D4: =scenario_indirect_prod_4506_iotable_2020_xlsx_3[[#This Row],[2027]]+scenario_indirect_prod_1610_iotable_2020_xlsx_3[[#This Row],[2027]] -> 24566.103 | E4: =scenario_indirect_prod_4506_iotable_2020_xlsx_3[[#This Row],[2028]]+scenario_indirect_prod_1610_iotable_2020_xlsx_3[[#This Row],[2028]] -> 25551.341 | F4: =scenario_indirect_prod_4506_iotable_2020_xlsx_3[[#This Row],[2029]]+scenario_indirect_prod_1610_iotable_2020_xlsx_3[[#This Row],[2029]] -> 27065.504 | G4: =scenario_indirect_prod_4506_iotable_2020_xlsx_3[[#This Row],[2030]]+scenario_indirect_prod_1610_iotable_2020_xlsx_3[[#This Row],[2030]] -> 33056.031 | H4: =scenario_indirect_prod_4506_iotable_2020_xlsx_3[[#This Row],[2031]]+scenario_indirect_prod_1610_iotable_2020_xlsx_3[[#This Row],[2031]] -> 34385.314 | I4: =scenario_indirect_prod_4506_iotable_2020_xlsx_3[[#This Row],[2032]]+scenario_indirect_prod_1610_iotable_2020_xlsx_3[[#This Row],[2032]] -> 36241.776 | J4: =scenario_indirect_prod_4506_iotable_2020_xlsx_3[[#This Row],[2033]]+scenario_indirect_prod_1610_iotable_2020_xlsx_3[[#This Row],[2033]] -> 42956.841 | K4: =scenario_indirect_prod_4506_iotable_2020_xlsx_3[[#This Row],[2034]]+scenario_indirect_prod_1610_iotable_2020_xlsx_3[[#This Row],[2034]] -> 44684.376 | L4: =scenario_indirect_prod_4506_iotable_2020_xlsx_3[[#This Row],[2035]]+scenario_indirect_prod_1610_iotable_2020_xlsx_3[[#This Row],[2035]] -> 53810.389 | M4: =scenario_indirect_prod_4506_iotable_2020_xlsx_3[[#This Row],[2036]]+scenario_indirect_prod_1610_iotable_2020_xlsx_3[[#This Row],[2036]] -> 58521.045 | N4: =scenario_indirect_prod_4506_iotable_2020_xlsx_3[[#This Row],[2037]]+scenario_indirect_prod_1610_iotable_2020_xlsx_3[[#This Row],[2037]] -> 62708.929 | O4: =scenario_indirect_prod_4506_iotable_2020_xlsx_3[[#This Row],[2038]]+scenario_indirect_prod_1610_iotable_2020_xlsx_3[[#This Row],[2038]] -> 62708.929 | P4: =scenario_indirect_prod_4506_iotable_2020_xlsx_3[[#This Row],[2039]]+scenario_indirect_prod_1610_iotable_2020_xlsx_3[[#This Row],[2039]] -> 62708.929 | Q4: =scenario_indirect_prod_4506_iotable_2020_xlsx_3[[#This Row],[2040]]+scenario_indirect_prod_1610_iotable_2020_xlsx_3[[#This Row],[2040]] -> 66373.544 | R4: =scenario_indirect_prod_4506_iotable_2020_xlsx_3[[#This Row],[2041]]+scenario_indirect_prod_1610_iotable_2020_xlsx_3[[#This Row],[2041]] -> 66373.544 | S4: =scenario_indirect_prod_4506_iotable_2020_xlsx_3[[#This Row],[2042]]+scenario_indirect_prod_1610_iotable_2020_xlsx_3[[#This Row],[2042]] -> 70456.126 | T4: =scenario_indirect_prod_4506_iotable_2020_xlsx_3[[#This Row],[2043]]+scenario_indirect_prod_1610_iotable_2020_xlsx_3[[#This Row],[2043]] -> 70456.126 | U4: =scenario_indirect_prod_4506_iotable_2020_xlsx_3[[#This Row],[2044]]+scenario_indirect_prod_1610_iotable_2020_xlsx_3[[#This Row],[2044]] -> 74224.393 | V4: =scenario_indirect_prod_4506_iotable_2020_xlsx_3[[#This Row],[2045]]+scenario_indirect_prod_1610_iotable_2020_xlsx_3[[#This Row],[2045]] -> 74224.393 | W4: =scenario_indirect_prod_4506_iotable_2020_xlsx_3[[#This Row],[2046]]+scenario_indirect_prod_1610_iotable_2020_xlsx_3[[#This Row],[2046]] -> 77469.225 | X4: =scenario_indirect_prod_4506_iotable_2020_xlsx_3[[#This Row],[2047]]+scenario_indirect_prod_1610_iotable_2020_xlsx_3[[#This Row],[2047]] -> 77469.225 | Y4: =scenario_indirect_prod_4506_iotable_2020_xlsx_3[[#This Row],[2048]]+scenario_indirect_prod_1610_iotable_2020_xlsx_3[[#This Row],[2048]] -> 77469.225 | Z4: =scenario_indirect_prod_4506_iotable_2020_xlsx_3[[#This Row],[2049]]+scenario_indirect_prod_1610_iotable_2020_xlsx_3[[#This Row],[2049]] -> 77469.225 | AA4: =scenario_indirect_prod_4506_iotable_2020_xlsx_3[[#This Row],[2050]]+scenario_indirect_prod_1610_iotable_2020_xlsx_3[[#This Row],[2050]] -> 77469.225
A5: 0114 | B5: 감자류 | C5: =scenario_indirect_prod_4506_iotable_2020_xlsx_3[[#This Row],[2026]]+scenario_indirect_prod_1610_iotable_2020_xlsx_3[[#This Row],[2026]] -> 894.44266 | D5: =scenario_indirect_prod_4506_iotable_2020_xlsx_3[[#This Row],[2027]]+scenario_indirect_prod_1610_iotable_2020_xlsx_3[[#This Row],[2027]] -> 895.69186 | E5: =scenario_indirect_prod_4506_iotable_2020_xlsx_3[[#This Row],[2028]]+scenario_indirect_prod_1610_iotable_2020_xlsx_3[[#This Row],[2028]] -> 939.51854 | F5: =scenario_indirect_prod_4506_iotable_2020_xlsx_3[[#This Row],[2029]]+scenario_indirect_prod_1610_iotable_2020_xlsx_3[[#This Row],[2029]] -> 971.21662 | G5: =scenario_indirect_prod_4506_iotable_2020_xlsx_3[[#This Row],[2030]]+scenario_indirect_prod_1610_iotable_2020_xlsx_3[[#This Row],[2030]] -> 935.45476 | H5: =scenario_indirect_prod_4506_iotable_2020_xlsx_3[[#This Row],[2031]]+scenario_indirect_prod_1610_iotable_2020_xlsx_3[[#This Row],[2031]] -> 994.58569 | I5: =scenario_indirect_prod_4506_iotable_2020_xlsx_3[[#This Row],[2032]]+scenario_indirect_prod_1610_iotable_2020_xlsx_3[[#This Row],[2032]] -> 1077.1673 | J5: =scenario_indirect_prod_4506_iotable_2020_xlsx_3[[#This Row],[2033]]+scenario_indirect_prod_1610_iotable_2020_xlsx_3[[#This Row],[2033]] -> 1207.2704 | K5: =scenario_indirect_prod_4506_iotable_2020_xlsx_3[[#This Row],[2034]]+scenario_indirect_prod_1610_iotable_2020_xlsx_3[[#This Row],[2034]] -> 1284.1169 | L5: =scenario_indirect_prod_4506_iotable_2020_xlsx_3[[#This Row],[2035]]+scenario_indirect_prod_1610_iotable_2020_xlsx_3[[#This Row],[2035]] -> 1476.6381 | M5: =scenario_indirect_prod_4506_iotable_2020_xlsx_3[[#This Row],[2036]]+scenario_indirect_prod_1610_iotable_2020_xlsx_3[[#This Row],[2036]] -> 1546.0898 | N5: =scenario_indirect_prod_4506_iotable_2020_xlsx_3[[#This Row],[2037]]+scenario_indirect_prod_1610_iotable_2020_xlsx_3[[#This Row],[2037]] -> 1609.9099 | O5: =scenario_indirect_prod_4506_iotable_2020_xlsx_3[[#This Row],[2038]]+scenario_indirect_prod_1610_iotable_2020_xlsx_3[[#This Row],[2038]] -> 1609.9099 | P5: =scenario_indirect_prod_4506_iotable_2020_xlsx_3[[#This Row],[2039]]+scenario_indirect_prod_1610_iotable_2020_xlsx_3[[#This Row],[2039]] -> 1609.9099 | Q5: =scenario_indirect_prod_4506_iotable_2020_xlsx_3[[#This Row],[2040]]+scenario_indirect_prod_1610_iotable_2020_xlsx_3[[#This Row],[2040]] -> 1665.406 | R5: =scenario_indirect_prod_4506_iotable_2020_xlsx_3[[#This Row],[2041]]+scenario_indirect_prod_1610_iotable_2020_xlsx_3[[#This Row],[2041]] -> 1665.406 | S5: =scenario_indirect_prod_4506_iotable_2020_xlsx_3[[#This Row],[2042]]+scenario_indirect_prod_1610_iotable_2020_xlsx_3[[#This Row],[2042]] -> 1728.3394 | T5: =scenario_indirect_prod_4506_iotable_2020_xlsx_3[[#This Row],[2043]]+scenario_indirect_prod_1610_iotable_2020_xlsx_3[[#This Row],[2043]] -> 1728.3394 | U5: =scenario_indirect_prod_4506_iotable_2020_xlsx_3[[#This Row],[2044]]+scenario_indirect_prod_1610_iotable_2020_xlsx_3[[#This Row],[2044]] -> 1783.1061 | V5: =scenario_indirect_prod_4506_iotable_2020_xlsx_3[[#This Row],[2045]]+scenario_indirect_prod_1610_iotable_2020_xlsx_3[[#This Row],[2045]] -> 1783.1061 | W5: =scenario_indirect_prod_4506_iotable_2020_xlsx_3[[#This Row],[2046]]+scenario_indirect_prod_1610_iotable_2020_xlsx_3[[#This Row],[2046]] -> 1831.3512 | X5: =scenario_indirect_prod_4506_iotable_2020_xlsx_3[[#This Row],[2047]]+scenario_indirect_prod_1610_iotable_2020_xlsx_3[[#This Row],[2047]] -> 1831.3512 | Y5: =scenario_indirect_prod_4506_iotable_2020_xlsx_3[[#This Row],[2048]]+scenario_indirect_prod_1610_iotable_2020_xlsx_3[[#This Row],[2048]] -> 1831.3512 | Z5: =scenario_indirect_prod_4506_iotable_2020_xlsx_3[[#This Row],[2049]]+scenario_indirect_prod_1610_iotable_2020_xlsx_3[[#This Row],[2049]] -> 1831.3512 | AA5: =scenario_indirect_prod_4506_iotable_2020_xlsx_3[[#This Row],[2050]]+scenario_indirect_prod_1610_iotable_2020_xlsx_3[[#This Row],[2050]] -> 1831.3512
A6: 0121 | B6: 채소 | C6: =scenario_indirect_prod_4506_iotable_2020_xlsx_3[[#This Row],[2026]]+scenario_indirect_prod_1610_iotable_2020_xlsx_3[[#This Row],[2026]] -> 6963.5743 | D6: =scenario_indirect_prod_4506_iotable_2020_xlsx_3[[#This Row],[2027]]+scenario_indirect_prod_1610_iotable_2020_xlsx_3[[#This Row],[2027]] -> 6829.1619 | E6: =scenario_indirect_prod_4506_iotable_2020_xlsx_3[[#This Row],[2028]]+scenario_indirect_prod_1610_iotable_2020_xlsx_3[[#This Row],[2028]] -> 7178.9361 | F6: =scenario_indirect_prod_4506_iotable_2020_xlsx_3[[#This Row],[2029]]+scenario_indirect_prod_1610_iotable_2020_xlsx_3[[#This Row],[2029]] -> 7374.1609 | G6: =scenario_indirect_prod_4506_iotable_2020_xlsx_3[[#This Row],[2030]]+scenario_indirect_prod_1610_iotable_2020_xlsx_3[[#This Row],[2030]] -> 6599.217 | H6: =scenario_indirect_prod_4506_iotable_2020_xlsx_3[[#This Row],[2031]]+scenario_indirect_prod_1610_iotable_2020_xlsx_3[[#This Row],[2031]] -> 7071.1323 | I6: =scenario_indirect_prod_4506_iotable_2020_xlsx_3[[#This Row],[2032]]+scenario_indirect_prod_1610_iotable_2020_xlsx_3[[#This Row],[2032]] -> 7730.2039 | J6: =scenario_indirect_prod_4506_iotable_2020_xlsx_3[[#This Row],[2033]]+scenario_indirect_prod_1610_iotable_2020_xlsx_3[[#This Row],[2033]] -> 8495.4508 | K6: =scenario_indirect_prod_4506_iotable_2020_xlsx_3[[#This Row],[2034]]+scenario_indirect_prod_1610_iotable_2020_xlsx_3[[#This Row],[2034]] -> 9108.7513 | L6: =scenario_indirect_prod_4506_iotable_2020_xlsx_3[[#This Row],[2035]]+scenario_indirect_prod_1610_iotable_2020_xlsx_3[[#This Row],[2035]] -> 10299.539 | M6: =scenario_indirect_prod_4506_iotable_2020_xlsx_3[[#This Row],[2036]]+scenario_indirect_prod_1610_iotable_2020_xlsx_3[[#This Row],[2036]] -> 10626.915 | N6: =scenario_indirect_prod_4506_iotable_2020_xlsx_3[[#This Row],[2037]]+scenario_indirect_prod_1610_iotable_2020_xlsx_3[[#This Row],[2037]] -> 10937.889 | O6: =scenario_indirect_prod_4506_iotable_2020_xlsx_3[[#This Row],[2038]]+scenario_indirect_prod_1610_iotable_2020_xlsx_3[[#This Row],[2038]] -> 10937.889 | P6: =scenario_indirect_prod_4506_iotable_2020_xlsx_3[[#This Row],[2039]]+scenario_indirect_prod_1610_iotable_2020_xlsx_3[[#This Row],[2039]] -> 10937.889 | Q6: =scenario_indirect_prod_4506_iotable_2020_xlsx_3[[#This Row],[2040]]+scenario_indirect_prod_1610_iotable_2020_xlsx_3[[#This Row],[2040]] -> 11206.65 | R6: =scenario_indirect_prod_4506_iotable_2020_xlsx_3[[#This Row],[2041]]+scenario_indirect_prod_1610_iotable_2020_xlsx_3[[#This Row],[2041]] -> 11206.65 | S6: =scenario_indirect_prod_4506_iotable_2020_xlsx_3[[#This Row],[2042]]+scenario_indirect_prod_1610_iotable_2020_xlsx_3[[#This Row],[2042]] -> 11516.7 | T6: =scenario_indirect_prod_4506_iotable_2020_xlsx_3[[#This Row],[2043]]+scenario_indirect_prod_1610_iotable_2020_xlsx_3[[#This Row],[2043]] -> 11516.7 | U6: =scenario_indirect_prod_4506_iotable_2020_xlsx_3[[#This Row],[2044]]+scenario_indirect_prod_1610_iotable_2020_xlsx_3[[#This Row],[2044]] -> 11770.989 | V6: =scenario_indirect_prod_4506_iotable_2020_xlsx_3[[#This Row],[2045]]+scenario_indirect_prod_1610_iotable_2020_xlsx_3[[#This Row],[2045]] -> 11770.989 | W6: =scenario_indirect_prod_4506_iotable_2020_xlsx_3[[#This Row],[2046]]+scenario_indirect_prod_1610_iotable_2020_xlsx_3[[#This Row],[2046]] -> 12000.382 | X6: =scenario_indirect_prod_4506_iotable_2020_xlsx_3[[#This Row],[2047]]+scenario_indirect_prod_1610_iotable_2020_xlsx_3[[#This Row],[2047]] -> 12000.382 | Y6: =scenario_indirect_prod_4506_iotable_2020_xlsx_3[[#This Row],[2048]]+scenario_indirect_prod_1610_iotable_2020_xlsx_3[[#This Row],[2048]] -> 12000.382 | Z6: =scenario_indirect_prod_4506_iotable_2020_xlsx_3[[#This Row],[2049]]+scenario_indirect_prod_1610_iotable_2020_xlsx_3[[#This Row],[2049]] -> 12000.382 | AA6: =scenario_indirect_prod_4506_iotable_2020_xlsx_3[[#This Row],[2050]]+scenario_indirect_prod_1610_iotable_2020_xlsx_3[[#This Row],[2050]] -> 12000.382
A7: 0122 | B7: 과실 | C7: =scenario_indirect_prod_4506_iotable_2020_xlsx_3[[#This Row],[2026]]+scenario_indirect_prod_1610_iotable_2020_xlsx_3[[#This Row],[2026]] -> 2637.2078 | D7: =scenario_indirect_prod_4506_iotable_2020_xlsx_3[[#This Row],[2027]]+scenario_indirect_prod_1610_iotable_2020_xlsx_3[[#This Row],[2027]] -> 2495.4879 | E7: =scenario_indirect_prod_4506_iotable_2020_xlsx_3[[#This Row],[2028]]+scenario_indirect_prod_1610_iotable_2020_xlsx_3[[#This Row],[2028]] -> 2633.3503 | F7: =scenario_indirect_prod_4506_iotable_2020_xlsx_3[[#This Row],[2029]]+scenario_indirect_prod_1610_iotable_2020_xlsx_3[[#This Row],[2029]] -> 2674.8009 | G7: =scenario_indirect_prod_4506_iotable_2020_xlsx_3[[#This Row],[2030]]+scenario_indirect_prod_1610_iotable_2020_xlsx_3[[#This Row],[2030]] -> 2068.4773 | H7: =scenario_indirect_prod_4506_iotable_2020_xlsx_3[[#This Row],[2031]]+scenario_indirect_prod_1610_iotable_2020_xlsx_3[[#This Row],[2031]] -> 2254.4811 | I7: =scenario_indirect_prod_4506_iotable_2020_xlsx_3[[#This Row],[2032]]+scenario_indirect_prod_1610_iotable_2020_xlsx_3[[#This Row],[2032]] -> 2514.2521 | J7: =scenario_indirect_prod_4506_iotable_2020_xlsx_3[[#This Row],[2033]]+scenario_indirect_prod_1610_iotable_2020_xlsx_3[[#This Row],[2033]] -> 2648.0242 | K7: =scenario_indirect_prod_4506_iotable_2020_xlsx_3[[#This Row],[2034]]+scenario_indirect_prod_1610_iotable_2020_xlsx_3[[#This Row],[2034]] -> 2889.7546 | L7: =scenario_indirect_prod_4506_iotable_2020_xlsx_3[[#This Row],[2035]]+scenario_indirect_prod_1610_iotable_2020_xlsx_3[[#This Row],[2035]] -> 3146.6249 | M7: =scenario_indirect_prod_4506_iotable_2020_xlsx_3[[#This Row],[2036]]+scenario_indirect_prod_1610_iotable_2020_xlsx_3[[#This Row],[2036]] -> 3136.1947 | N7: =scenario_indirect_prod_4506_iotable_2020_xlsx_3[[#This Row],[2037]]+scenario_indirect_prod_1610_iotable_2020_xlsx_3[[#This Row],[2037]] -> 3136.8437 | O7: =scenario_indirect_prod_4506_iotable_2020_xlsx_3[[#This Row],[2038]]+scenario_indirect_prod_1610_iotable_2020_xlsx_3[[#This Row],[2038]] -> 3136.8437 | P7: =scenario_indirect_prod_4506_iotable_2020_xlsx_3[[#This Row],[2039]]+scenario_indirect_prod_1610_iotable_2020_xlsx_3[[#This Row],[2039]] -> 3136.8437 | Q7: =scenario_indirect_prod_4506_iotable_2020_xlsx_3[[#This Row],[2040]]+scenario_indirect_prod_1610_iotable_2020_xlsx_3[[#This Row],[2040]] -> 3135.7403 | R7: =scenario_indirect_prod_4506_iotable_2020_xlsx_3[[#This Row],[2041]]+scenario_indirect_prod_1610_iotable_2020_xlsx_3[[#This Row],[2041]] -> 3135.7403 | S7: =scenario_indirect_prod_4506_iotable_2020_xlsx_3[[#This Row],[2042]]+scenario_indirect_prod_1610_iotable_2020_xlsx_3[[#This Row],[2042]] -> 3139.8051 | T7: =scenario_indirect_prod_4506_iotable_2020_xlsx_3[[#This Row],[2043]]+scenario_indirect_prod_1610_iotable_2020_xlsx_3[[#This Row],[2043]] -> 3139.8051 | U7: =scenario_indirect_prod_4506_iotable_2020_xlsx_3[[#This Row],[2044]]+scenario_indirect_prod_1610_iotable_2020_xlsx_3[[#This Row],[2044]] -> 3127.6813 | V7: =scenario_indirect_prod_4506_iotable_2020_xlsx_3[[#This Row],[2045]]+scenario_indirect_prod_1610_iotable_2020_xlsx_3[[#This Row],[2045]] -> 3127.6813 | W7: =scenario_indirect_prod_4506_iotable_2020_xlsx_3[[#This Row],[2046]]+scenario_indirect_prod_1610_iotable_2020_xlsx_3[[#This Row],[2046]] -> 3122.4317 | X7: =scenario_indirect_prod_4506_iotable_2020_xlsx_3[[#This Row],[2047]]+scenario_indirect_prod_1610_iotable_2020_xlsx_3[[#This Row],[2047]] -> 3122.4317 | Y7: =scenario_indirect_prod_4506_iotable_2020_xlsx_3[[#This Row],[2048]]+scenario_indirect_prod_1610_iotable_2020_xlsx_3[[#This Row],[2048]] -> 3122.4317 | Z7: =scenario_indirect_prod_4506_iotable_2020_xlsx_3[[#This Row],[2049]]+scenario_indirect_prod_1610_iotable_2020_xlsx_3[[#This Row],[2049]] -> 3122.4317 | AA7: =scenario_indirect_prod_4506_iotable_2020_xlsx_3[[#This Row],[2050]]+scenario_indirect_prod_1610_iotable_2020_xlsx_3[[#This Row],[2050]] -> 3122.4317
A8: 0191 | B8: 화훼작물 | C8: =scenario_indirect_prod_4506_iotable_2020_xlsx_3[[#This Row],[2026]]+scenario_indirect_prod_1610_iotable_2020_xlsx_3[[#This Row],[2026]] -> 649.73288 | D8: =scenario_indirect_prod_4506_iotable_2020_xlsx_3[[#This Row],[2027]]+scenario_indirect_prod_1610_iotable_2020_xlsx_3[[#This Row],[2027]] -> 627.4327 | E8: =scenario_indirect_prod_4506_iotable_2020_xlsx_3[[#This Row],[2028]]+scenario_indirect_prod_1610_iotable_2020_xlsx_3[[#This Row],[2028]] -> 660.64824 | F8: =scenario_indirect_prod_4506_iotable_2020_xlsx_3[[#This Row],[2029]]+scenario_indirect_prod_1610_iotable_2020_xlsx_3[[#This Row],[2029]] -> 675.37294 | G8: =scenario_indirect_prod_4506_iotable_2020_xlsx_3[[#This Row],[2030]]+scenario_indirect_prod_1610_iotable_2020_xlsx_3[[#This Row],[2030]] -> 569.44991 | H8: =scenario_indirect_prod_4506_iotable_2020_xlsx_3[[#This Row],[2031]]+scenario_indirect_prod_1610_iotable_2020_xlsx_3[[#This Row],[2031]] -> 614.26431 | I8: =scenario_indirect_prod_4506_iotable_2020_xlsx_3[[#This Row],[2032]]+scenario_indirect_prod_1610_iotable_2020_xlsx_3[[#This Row],[2032]] -> 676.8516 | J8: =scenario_indirect_prod_4506_iotable_2020_xlsx_3[[#This Row],[2033]]+scenario_indirect_prod_1610_iotable_2020_xlsx_3[[#This Row],[2033]] -> 731.48504 | K8: =scenario_indirect_prod_4506_iotable_2020_xlsx_3[[#This Row],[2034]]+scenario_indirect_prod_1610_iotable_2020_xlsx_3[[#This Row],[2034]] -> 789.72578 | L8: =scenario_indirect_prod_4506_iotable_2020_xlsx_3[[#This Row],[2035]]+scenario_indirect_prod_1610_iotable_2020_xlsx_3[[#This Row],[2035]] -> 879.97422 | M8: =scenario_indirect_prod_4506_iotable_2020_xlsx_3[[#This Row],[2036]]+scenario_indirect_prod_1610_iotable_2020_xlsx_3[[#This Row],[2036]] -> 896.07618 | N8: =scenario_indirect_prod_4506_iotable_2020_xlsx_3[[#This Row],[2037]]+scenario_indirect_prod_1610_iotable_2020_xlsx_3[[#This Row],[2037]] -> 912.50584 | O8: =scenario_indirect_prod_4506_iotable_2020_xlsx_3[[#This Row],[2038]]+scenario_indirect_prod_1610_iotable_2020_xlsx_3[[#This Row],[2038]] -> 912.50584 | P8: =scenario_indirect_prod_4506_iotable_2020_xlsx_3[[#This Row],[2039]]+scenario_indirect_prod_1610_iotable_2020_xlsx_3[[#This Row],[2039]] -> 912.50584 | Q8: =scenario_indirect_prod_4506_iotable_2020_xlsx_3[[#This Row],[2040]]+scenario_indirect_prod_1610_iotable_2020_xlsx_3[[#This Row],[2040]] -> 926.52642 | R8: =scenario_indirect_prod_4506_iotable_2020_xlsx_3[[#This Row],[2041]]+scenario_indirect_prod_1610_iotable_2020_xlsx_3[[#This Row],[2041]] -> 926.52642 | S8: =scenario_indirect_prod_4506_iotable_2020_xlsx_3[[#This Row],[2042]]+scenario_indirect_prod_1610_iotable_2020_xlsx_3[[#This Row],[2042]] -> 943.27446 | T8: =scenario_indirect_prod_4506_iotable_2020_xlsx_3[[#This Row],[2043]]+scenario_indirect_prod_1610_iotable_2020_xlsx_3[[#This Row],[2043]] -> 943.27446 | U8: =scenario_indirect_prod_4506_iotable_2020_xlsx_3[[#This Row],[2044]]+scenario_indirect_prod_1610_iotable_2020_xlsx_3[[#This Row],[2044]] -> 955.34947 | V8: =scenario_indirect_prod_4506_iotable_2020_xlsx_3[[#This Row],[2045]]+scenario_indirect_prod_1610_iotable_2020_xlsx_3[[#This Row],[2045]] -> 955.34947 | W8: =scenario_indirect_prod_4506_iotable_2020_xlsx_3[[#This Row],[2046]]+scenario_indirect_prod_1610_iotable_2020_xlsx_3[[#This Row],[2046]] -> 966.85337 | X8: =scenario_indirect_prod_4506_iotable_2020_xlsx_3[[#This Row],[2047]]+scenario_indirect_prod_1610_iotable_2020_xlsx_3[[#This Row],[2047]] -> 966.85337 | Y8: =scenario_indirect_prod_4506_iotable_2020_xlsx_3[[#This Row],[2048]]+scenario_indirect_prod_1610_iotable_2020_xlsx_3[[#This Row],[2048]] -> 966.85337 | Z8: =scenario_indirect_prod_4506_iotable_2020_xlsx_3[[#This Row],[2049]]+scenario_indirect_prod_1610_iotable_2020_xlsx_3[[#This Row],[2049]] -> 966.85337 | AA8: =scenario_indirect_prod_4506_iotable_2020_xlsx_3[[#This Row],[2050]]+scenario_indirect_prod_1610_iotable_2020_xlsx_3[[#This Row],[2050]] -> 966.85337
A9: 0192 | B9: 약용작물 | C9: =scenario_indirect_prod_4506_iotable_2020_xlsx_3[[#This Row],[2026]]+scenario_indirect_prod_1610_iotable_2020_xlsx_3[[#This Row],[2026]] -> 368.49268 | D9: =scenario_indirect_prod_4506_iotable_2020_xlsx_3[[#This Row],[2027]]+scenario_indirect_prod_1610_iotable_2020_xlsx_3[[#This Row],[2027]] -> 339.90739 | E9: =scenario_indirect_prod_4506_iotable_2020_xlsx_3[[#This Row],[2028]]+scenario_indirect_prod_1610_iotable_2020_xlsx_3[[#This Row],[2028]] -> 359.6927 | F9: =scenario_indirect_prod_4506_iotable_2020_xlsx_3[[#This Row],[2029]]+scenario_indirect_prod_1610_iotable_2020_xlsx_3[[#This Row],[2029]] -> 362.34293 | G9: =scenario_indirect_prod_4506_iotable_2020_xlsx_3[[#This Row],[2030]]+scenario_indirect_prod_1610_iotable_2020_xlsx_3[[#This Row],[2030]] -> 247.36677 | H9: =scenario_indirect_prod_4506_iotable_2020_xlsx_3[[#This Row],[2031]]+scenario_indirect_prod_1610_iotable_2020_xlsx_3[[#This Row],[2031]] -> 274.0611 | I9: =scenario_indirect_prod_4506_iotable_2020_xlsx_3[[#This Row],[2032]]+scenario_indirect_prod_1610_iotable_2020_xlsx_3[[#This Row],[2032]] -> 311.34212 | J9: =scenario_indirect_prod_4506_iotable_2020_xlsx_3[[#This Row],[2033]]+scenario_indirect_prod_1610_iotable_2020_xlsx_3[[#This Row],[2033]] -> 314.94307 | K9: =scenario_indirect_prod_4506_iotable_2020_xlsx_3[[#This Row],[2034]]+scenario_indirect_prod_1610_iotable_2020_xlsx_3[[#This Row],[2034]] -> 349.635 | L9: =scenario_indirect_prod_4506_iotable_2020_xlsx_3[[#This Row],[2035]]+scenario_indirect_prod_1610_iotable_2020_xlsx_3[[#This Row],[2035]] -> 366.75535 | M9: =scenario_indirect_prod_4506_iotable_2020_xlsx_3[[#This Row],[2036]]+scenario_indirect_prod_1610_iotable_2020_xlsx_3[[#This Row],[2036]] -> 352.29864 | N9: =scenario_indirect_prod_4506_iotable_2020_xlsx_3[[#This Row],[2037]]+scenario_indirect_prod_1610_iotable_2020_xlsx_3[[#This Row],[2037]] -> 341.06224 | O9: =scenario_indirect_prod_4506_iotable_2020_xlsx_3[[#This Row],[2038]]+scenario_indirect_prod_1610_iotable_2020_xlsx_3[[#This Row],[2038]] -> 341.06224 | P9: =scenario_indirect_prod_4506_iotable_2020_xlsx_3[[#This Row],[2039]]+scenario_indirect_prod_1610_iotable_2020_xlsx_3[[#This Row],[2039]] -> 341.06224 | Q9: =scenario_indirect_prod_4506_iotable_2020_xlsx_3[[#This Row],[2040]]+scenario_indirect_prod_1610_iotable_2020_xlsx_3[[#This Row],[2040]] -> 330.95759 | R9: =scenario_indirect_prod_4506_iotable_2020_xlsx_3[[#This Row],[2041]]+scenario_indirect_prod_1610_iotable_2020_xlsx_3[[#This Row],[2041]] -> 330.95759 | S9: =scenario_indirect_prod_4506_iotable_2020_xlsx_3[[#This Row],[2042]]+scenario_indirect_prod_1610_iotable_2020_xlsx_3[[#This Row],[2042]] -> 320.56272 | T9: =scenario_indirect_prod_4506_iotable_2020_xlsx_3[[#This Row],[2043]]+scenario_indirect_prod_1610_iotable_2020_xlsx_3[[#This Row],[2043]] -> 320.56272 | U9: =scenario_indirect_prod_4506_iotable_2020_xlsx_3[[#This Row],[2044]]+scenario_indirect_prod_1610_iotable_2020_xlsx_3[[#This Row],[2044]] -> 308.38245 | V9: =scenario_indirect_prod_4506_iotable_2020_xlsx_3[[#This Row],[2045]]+scenario_indirect_prod_1610_iotable_2020_xlsx_3[[#This Row],[2045]] -> 308.38245 | W9: =scenario_indirect_prod_4506_iotable_2020_xlsx_3[[#This Row],[2046]]+scenario_indirect_prod_1610_iotable_2020_xlsx_3[[#This Row],[2046]] -> 298.73943 | X9: =scenario_indirect_prod_4506_iotable_2020_xlsx_3[[#This Row],[2047]]+scenario_indirect_prod_1610_iotable_2020_xlsx_3[[#This Row],[2047]] -> 298.73943 | Y9: =scenario_indirect_prod_4506_iotable_2020_xlsx_3[[#This Row],[2048]]+scenario_indirect_prod_1610_iotable_2020_xlsx_3[[#This Row],[2048]] -> 298.73943 | Z9: =scenario_indirect_prod_4506_iotable_2020_xlsx_3[[#This Row],[2049]]+scenario_indirect_prod_1610_iotable_2020_xlsx_3[[#This Row],[2049]] -> 298.73943 | AA9: =scenario_indirect_prod_4506_iotable_2020_xlsx_3[[#This Row],[2050]]+scenario_indirect_prod_1610_iotable_2020_xlsx_3[[#This Row],[2050]] -> 298.73943
A10: 0193 | B10: 잎담배 | C10: =scenario_indirect_prod_4506_iotable_2020_xlsx_3[[#This Row],[2026]]+scenario_indirect_prod_1610_iotable_2020_xlsx_3[[#This Row],[2026]] -> 0 | D10: =scenario_indirect_prod_4506_iotable_2020_xlsx_3[[#This Row],[2027]]+scenario_indirect_prod_1610_iotable_2020_xlsx_3[[#This Row],[2027]] -> 0 | E10: =scenario_indirect_prod_4506_iotable_2020_xlsx_3[[#This Row],[2028]]+scenario_indirect_prod_1610_iotable_2020_xlsx_3[[#This Row],[2028]] -> 0 | F10: =scenario_indirect_prod_4506_iotable_2020_xlsx_3[[#This Row],[2029]]+scenario_indirect_prod_1610_iotable_2020_xlsx_3[[#This Row],[2029]] -> 0 | G10: =scenario_indirect_prod_4506_iotable_2020_xlsx_3[[#This Row],[2030]]+scenario_indirect_prod_1610_iotable_2020_xlsx_3[[#This Row],[2030]] -> 0 | H10: =scenario_indirect_prod_4506_iotable_2020_xlsx_3[[#This Row],[2031]]+scenario_indirect_prod_1610_iotable_2020_xlsx_3[[#This Row],[2031]] -> 0 | I10: =scenario_indirect_prod_4506_iotable_2020_xlsx_3[[#This Row],[2032]]+scenario_indirect_prod_1610_iotable_2020_xlsx_3[[#This Row],[2032]] -> 0 | J10: =scenario_indirect_prod_4506_iotable_2020_xlsx_3[[#This Row],[2033]]+scenario_indirect_prod_1610_iotable_2020_xlsx_3[[#This Row],[2033]] -> 0 | K10: =scenario_indirect_prod_4506_iotable_2020_xlsx_3[[#This Row],[2034]]+scenario_indirect_prod_1610_iotable_2020_xlsx_3[[#This Row],[2034]] -> 0 | L10: =scenario_indirect_prod_4506_iotable_2020_xlsx_3[[#This Row],[2035]]+scenario_indirect_prod_1610_iotable_2020_xlsx_3[[#This Row],[2035]] -> 0 | M10: =scenario_indirect_prod_4506_iotable_2020_xlsx_3[[#This Row],[2036]]+scenario_indirect_prod_1610_iotable_2020_xlsx_3[[#This Row],[2036]] -> 0 | N10: =scenario_indirect_prod_4506_iotable_2020_xlsx_3[[#This Row],[2037]]+scenario_indirect_prod_1610_iotable_2020_xlsx_3[[#This Row],[2037]] -> 0 | O10: =scenario_indirect_prod_4506_iotable_2020_xlsx_3[[#This Row],[2038]]+scenario_indirect_prod_1610_iotable_2020_xlsx_3[[#This Row],[2038]] -> 0 | P10: =scenario_indirect_prod_4506_iotable_2020_xlsx_3[[#This Row],[2039]]+scenario_indirect_prod_1610_iotable_2020_xlsx_3[[#This Row],[2039]] -> 0 | Q10: =scenario_indirect_prod_4506_iotable_2020_xlsx_3[[#This Row],[2040]]+scenario_indirect_prod_1610_iotable_2020_xlsx_3[[#This Row],[2040]] -> 0 | R10: =scenario_indirect_prod_4506_iotable_2020_xlsx_3[[#This Row],[2041]]+scenario_indirect_prod_1610_iotable_2020_xlsx_3[[#This Row],[2041]] -> 0 | S10: =scenario_indirect_prod_4506_iotable_2020_xlsx_3[[#This Row],[2042]]+scenario_indirect_prod_1610_iotable_2020_xlsx_3[[#This Row],[2042]] -> 0 | T10: =scenario_indirect_prod_4506_iotable_2020_xlsx_3[[#This Row],[2043]]+scenario_indirect_prod_1610_iotable_2020_xlsx_3[[#This Row],[2043]] -> 0 | U10: =scenario_indirect_prod_4506_iotable_2020_xlsx_3[[#This Row],[2044]]+scenario_indirect_prod_1610_iotable_2020_xlsx_3[[#This Row],[2044]] -> 0 | V10: =scenario_indirect_prod_4506_iotable_2020_xlsx_3[[#This Row],[2045]]+scenario_indirect_prod_1610_iotable_2020_xlsx_3[[#This Row],[2045]] -> 0 | W10: =scenario_indirect_prod_4506_iotable_2020_xlsx_3[[#This Row],[2046]]+scenario_indirect_prod_1610_iotable_2020_xlsx_3[[#This Row],[2046]] -> 0 | X10: =scenario_indirect_prod_4506_iotable_2020_xlsx_3[[#This Row],[2047]]+scenario_indirect_prod_1610_iotable_2020_xlsx_3[[#This Row],[2047]] -> 0 | Y10: =scenario_indirect_prod_4506_iotable_2020_xlsx_3[[#This Row],[2048]]+scenario_indirect_prod_1610_iotable_2020_xlsx_3[[#This Row],[2048]] -> 0 | Z10: =scenario_indirect_prod_4506_iotable_2020_xlsx_3[[#This Row],[2049]]+scenario_indirect_prod_1610_iotable_2020_xlsx_3[[#This Row],[2049]] -> 0 | AA10: =scenario_indirect_prod_4506_iotable_2020_xlsx_3[[#This Row],[2050]]+scenario_indirect_prod_1610_iotable_2020_xlsx_3[[#This Row],[2050]] -> 0
