Workbook
Name \a: #REF!
Name \a: #REF!

Sheet integrated
A1: code | B1: sector | C1: unit | D1: 2023_중간수요계 | E1: 2023_최종수요계 | F1: 2023_총수요계 | G1: 2023_중간투입계(행합) | H1: 2023_부가가치계 | I1: 2025_중간수요계 | J1: 2025_최종수요계 | K1: 2025_총수요계 | L1: 2025_중간투입계(행합) | M1: 2025_부가가치계 | N1: 2030_중간수요계 | O1: 2030_최종수요계 | P1: 2030_총수요계 | Q1: 2030_중간투입계(행합) | R1: 2030_부가가치계 | S1: 2040_중간수요계 | T1: 2040_최종수요계 | U1: 2040_총수요계 | V1: 2040_중간투입계(행합) | W1: 2040_부가가치계
A2: 0111 | B2: 벼 | C2: 백만원 | D2: 0 | E2: 0 | F2: 0 | G2: 248598 | H2: 6195806 | I2: =D2*(1+0.01*growthrate!$E$3)^2 -> 0 | J2: =E2*(1+0.01*growthrate!$E$3)^2 -> 0 | K2: =F2*(1+0.01*growthrate!$E$3)^2 -> 0 | L2: =G2*(1+0.01*growthrate!$E$3)^2 -> 256111.87 | M2: =H2*(1+0.01*growthrate!$E$3)^2 -> 6383074.2 | N2: =I2*(1+0.01*growthrate!$E$3)^5 -> 0 | O2: =J2*(1+0.01*growthrate!$E$3)^5 -> 0 | P2: =K2*(1+0.01*growthrate!$E$3)^5 -> 0 | Q2: =L2*(1+0.01*growthrate!$E$3)^5 -> 275905.23 | R2: =M2*(1+0.01*growthrate!$E$3)^5 -> 6876383.8 | S2: =N2*(1+0.01*growthrate!$F$3)^10 -> 0 | T2: =O2*(1+0.01*growthrate!$F$3)^10 -> 0 | U2: =P2*(1+0.01*growthrate!$F$3)^10 -> 0 | V2: =Q2*(1+0.01*growthrate!$F$3)^10 -> 295838.46 | W2: =R2*(1+0.01*growthrate!$F$3)^10 -> 7373179.6
A3: 0112 | B3: 맥류 및 잡곡 | C3: 백만원 | D3: 6778410 | E3: 102197 | F3: 6880607 | G3: 11736 | H3: 196243 | I3: =D3*(1+0.01*growthrate!E4)^2 -> 7010834.9 | J3: =E3*(1+0.01*growthrate!$E$3)^2 -> 105285.9 | K3: =F3*(1+0.01*growthrate!$E$3)^2 -> 7088573.3 | L3: =G3*(1+0.01*growthrate!$E$3)^2 -> 12090.721 | M3: =H3*(1+0.01*growthrate!$E$3)^2 -> 202174.44 | N3: =I3*(1+0.01*growthrate!$E$3)^5 -> 7552660.3 | O3: =J3*(1+0.01*growthrate!$E$3)^5 -> 113422.82 | P3: =K3*(1+0.01*growthrate!$E$3)^5 -> 7636406.7 | Q3: =L3*(1+0.01*growthrate!$E$3)^5 -> 13025.14 | R3: =M3*(1+0.01*growthrate!$E$3)^5 -> 217799.3 | S3: =N3*(1+0.01*growthrate!$F$3)^10 -> 8098314.8 | T3: =O3*(1+0.01*growthrate!$F$3)^10 -> 121617.24 | U3: =P3*(1+0.01*growthrate!$F$3)^10 -> 8188111.6 | V3: =Q3*(1+0.01*growthrate!$F$3)^10 -> 13966.163 | W3: =R3*(1+0.01*growthrate!$F$3)^10 -> 233534.57
A4: 0113 | B4: 콩류 | C4: 백만원 | D4: 1047612 | E4: 280198 | F4: 1327810 | G4: 3157 | H4: 566246 | I4: =D4*(1+0.01*growthrate!E5)^2 -> 1047612 | J4: =E4*(1+0.01*growthrate!$E$3)^2 -> 288666.98 | K4: =F4*(1+0.01*growthrate!$E$3)^2 -> 1367943.1 | L4: =G4*(1+0.01*growthrate!$E$3)^2 -> 3252.4203 | M4: =H4*(1+0.01*growthrate!$E$3)^2 -> 583360.79 | N4: =I4*(1+0.01*growthrate!$E$3)^5 -> 1128575.6 | O4: =J4*(1+0.01*growthrate!$E$3)^5 -> 310976.32 | P4: =K4*(1+0.01*growthrate!$E$3)^5 -> 1473663.2 | Q4: =L4*(1+0.01*growthrate!$E$3)^5 -> 3503.7804 | R4: =M4*(1+0.01*growthrate!$E$3)^5 -> 628445.24 | S4: =N4*(1+0.01*growthrate!$F$3)^10 -> 1210111.5 | T4: =O4*(1+0.01*growthrate!$F$3)^10 -> 333443.33 | U4: =P4*(1+0.01*growthrate!$F$3)^10 -> 1580130.4 | V4: =Q4*(1+0.01*growthrate!$F$3)^10 -> 3756.9169 | W4: =R4*(1+0.01*growthrate!$F$3)^10 -> 673848.32
A5: 0114 | B5: 감자류 | C5: 백만원 | D5: 43309 | E5: 5701 | F5: 49010 | G5: 8846 | H5: 997863 | I5: =D5*(1+0.01*growthrate!E6)^2 -> 43309 | J5: =E5*(1+0.01*growthrate!$E$3)^2 -> 5873.3127 | K5: =F5*(1+0.01*growthrate!$E$3)^2 -> 50491.327 | L5: =G5*(1+0.01*growthrate!$E$3)^2 -> 9113.3703 | M5: =H5*(1+0.01*growthrate!$E$3)^2 -> 1028023.4 | N5: =I5*(1+0.01*growthrate!$E$3)^5 -> 46656.093 | O5: =J5*(1+0.01*growthrate!$E$3)^5 -> 6327.2258 | P5: =K5*(1+0.01*growthrate!$E$3)^5 -> 54393.499 | Q5: =L5*(1+0.01*growthrate!$E$3)^5 -> 9817.6881 | R5: =M5*(1+0.01*growthrate!$E$3)^5 -> 1107473.2 | S5: =N5*(1+0.01*growthrate!$F$3)^10 -> 50026.84 | T5: =O5*(1+0.01*growthrate!$F$3)^10 -> 6784.3468 | U5: =P5*(1+0.01*growthrate!$F$3)^10 -> 58323.248 | V5: =Q5*(1+0.01*growthrate!$F$3)^10 -> 10526.983 | W5: =R5*(1+0.01*growthrate!$F$3)^10 -> 1187484.4
A6: 0121 | B6: 채소 | C6: 백만원 | D6: 192086 | E6: 347759 | F6: 539845 | G6: 573328 | H6: 9078793 | I6: =D6*(1+0.01*growthrate!E7)^2 -> 192086 | J6: =E6*(1+0.01*growthrate!$E$3)^2 -> 358270.02 | K6: =F6*(1+0.01*growthrate!$E$3)^2 -> 556161.82 | L6: =G6*(1+0.01*growthrate!$E$3)^2 -> 590656.84 | M6: =H6*(1+0.01*growthrate!$E$3)^2 -> 9353199.5 | N6: =I6*(1+0.01*growthrate!$E$3)^5 -> 206931.18 | O6: =J6*(1+0.01*growthrate!$E$3)^5 -> 385958.56 | P6: =K6*(1+0.01*growthrate!$E$3)^5 -> 599144.23 | Q6: =L6*(1+0.01*growthrate!$E$3)^5 -> 636305.16 | R6: =M6*(1+0.01*growthrate!$E$3)^5 -> 10076052 | S6: =N6*(1+0.01*growthrate!$F$3)^10 -> 221881.26 | T6: =O6*(1+0.01*growthrate!$F$3)^10 -> 413842.78 | U6: =P6*(1+0.01*growthrate!$F$3)^10 -> 642430.4 | V6: =Q6*(1+0.01*growthrate!$F$3)^10 -> 682276.09 | W6: =R6*(1+0.01*growthrate!$F$3)^10 -> 10804013
A7: 0122 | B7: 과실 | C7: 백만원 | D7: 166506 | E7: 1630308 | F7: 1796814 | G7: 221302 | H7: 4313063 | I7: =D7*(1+0.01*growthrate!E8)^2 -> 166506 | J7: =E7*(1+0.01*growthrate!$E$3)^2 -> 1679584.1 | K7: =F7*(1+0.01*growthrate!$E$3)^2 -> 1851122.7 | L7: =G7*(1+0.01*growthrate!$E$3)^2 -> 227990.85 | M7: =H7*(1+0.01*growthrate!$E$3)^2 -> 4443425.3 | N7: =I7*(1+0.01*growthrate!$E$3)^5 -> 179374.25 | O7: =J7*(1+0.01*growthrate!$E$3)^5 -> 1809389 | P7: =K7*(1+0.01*growthrate!$E$3)^5 -> 1994184.9 | Q7: =L7*(1+0.01*growthrate!$E$3)^5 -> 245610.9 | R7: =M7*(1+0.01*growthrate!$E$3)^5 -> 4786831 | S7: =N7*(1+0.01*growthrate!$F$3)^10 -> 192333.44 | T7: =O7*(1+0.01*growthrate!$F$3)^10 -> 1940111.4 | U7: =P7*(1+0.01*growthrate!$F$3)^10 -> 2138258.1 | V7: =Q7*(1+0.01*growthrate!$F$3)^10 -> 263355.47 | W7: =R7*(1+0.01*growthrate!$F$3)^10 -> 5132663.6
A8: 0191 | B8: 화훼작물 | C8: 백만원 | D8: 40441 | E8: 131257 | F8: 171698 | G8: 85072 | H8: 268835 | I8: =D8*(1+0.01*growthrate!E9)^2 -> 40441 | J8: =E8*(1+0.01*growthrate!$E$3)^2 -> 135224.24 | K8: =F8*(1+0.01*growthrate!$E$3)^2 -> 176887.57 | L8: =G8*(1+0.01*growthrate!$E$3)^2 -> 87643.301 | M8: =H8*(1+0.01*growthrate!$E$3)^2 -> 276960.54 | N8: =I8*(1+0.01*growthrate!$E$3)^5 -> 43566.442 | O8: =J8*(1+0.01*growthrate!$E$3)^5 -> 145674.91 | P8: =K8*(1+0.01*growthrate!$E$3)^5 -> 190558.15 | Q8: =L8*(1+0.01*growthrate!$E$3)^5 -> 94416.726 | R8: =M8*(1+0.01*growthrate!$E$3)^5 -> 298365.16 | S8: =N8*(1+0.01*growthrate!$F$3)^10 -> 46713.973 | T8: =O8*(1+0.01*growthrate!$F$3)^10 -> 156199.44 | U8: =P8*(1+0.01*growthrate!$F$3)^10 -> 204325.34 | V8: =Q8*(1+0.01*growthrate!$F$3)^10 -> 101238.02 | W8: =R8*(1+0.01*growthrate!$F$3)^10 -> 319921.05
A9: 0192 | B9: 약용작물 | C9: 백만원 | D9: 139519 | E9: 98856 | F9: 238375 | G9: 27806 | H9: 1470976 | I9: =D9*(1+0.01*growthrate!E10)^2 -> 139519 | J9: =E9*(1+0.01*growthrate!$E$3)^2 -> 101843.92 | K9: =F9*(1+0.01*growthrate!$E$3)^2 -> 245579.88 | L9: =G9*(1+0.01*growthrate!$E$3)^2 -> 28646.436 | M9: =H9*(1+0.01*growthrate!$E$3)^2 -> 1515436.2 | N9: =I9*(1+0.01*growthrate!$E$3)^5 -> 150301.59 | O9: =J9*(1+0.01*growthrate!$E$3)^5 -> 109714.83 | P9: =K9*(1+0.01*growthrate!$E$3)^5 -> 264559.28 | Q9: =L9*(1+0.01*growthrate!$E$3)^5 -> 30860.348 | R9: =M9*(1+0.01*growthrate!$E$3)^5 -> 1632555.2 | S9: =N9*(1+0.01*growthrate!$F$3)^10 -> 161160.38 | T9: =O9*(1+0.01*growthrate!$F$3)^10 -> 117641.36 | U9: =P9*(1+0.01*growthrate!$F$3)^10 -> 283672.81 | V9: =Q9*(1+0.01*growthrate!$F$3)^10 -> 33089.905 | W9: =R9*(1+0.01*growthrate!$F$3)^10 -> 1750501.9
A10: 0193 | B10: 잎담배 | C10: 백만원 | D10: 382739 | E10: 22142 | F10: 404881 | G10: 666 | H10: 40059 | I10: =D10*(1+0.01*growthrate!E11)^2 -> 382739 | J10: =E10*(1+0.01*growthrate!$E$3)^2 -> 22811.242 | K10: =F10*(1+0.01*growthrate!$E$3)^2 -> 417118.53 | L10: =G10*(1+0.01*growthrate!$E$3)^2 -> 686.12985 | M10: =H10*(1+0.01*growthrate!$E$3)^2 -> 41269.783 | N10: =I10*(1+0.01*growthrate!$E$3)^5 -> 412318.6 | O10: =J10*(1+0.01*growthrate!$E$3)^5 -> 24574.186 | P10: =K10*(1+0.01*growthrate!$E$3)^5 -> 449355.12 | Q10: =L10*(1+0.01*growthrate!$E$3)^5 -> 739.15671 | R10: =M10*(1+0.01*growthrate!$E$3)^5 -> 44459.277 | S10: =N10*(1+0.01*growthrate!$F$3)^10 -> 442107.25 | T10: =O10*(1+0.01*growthrate!$F$3)^10 -> 26349.589 | U10: =P10*(1+0.01*growthrate!$F$3)^10 -> 481819.53 | V10: =Q10*(1+0.01*growthrate!$F$3)^10 -> 792.55832 | W10: =R10*(1+0.01*growthrate!$F$3)^10 -> 47671.312
A11: 0194 | B11: 천연고무 | C11: 백만원 | D11: 586461 | E11: -19365 | F11: 567096 | G11: 0 | H11: 0 | I11: =D11*(1+0.01*growthrate!E12)^2 -> 586461 | J11: =E11*(1+0.01*growthrate!$E$3)^2 -> -19950.307 | K11: =F11*(1+0.01*growthrate!$E$3)^2 -> 584236.48 | L11: =G11*(1+0.01*growthrate!$E$3)^2 -> 0 | M11: =H11*(1+0.01*growthrate!$E$3)^2 -> 0 | N11: =I11*(1+0.01*growthrate!$E$3)^5 -> 631785.05 | O11: =J11*(1+0.01*growthrate!$E$3)^5 -> -21492.147 | P11: =K11*(1+0.01*growthrate!$E$3)^5 -> 629388.61 | Q11: =L11*(1+0.01*growthrate!$E$3)^5 -> 0 | R11: =M11*(1+0.01*growthrate!$E$3)^5 -> 0 | S11: =N11*(1+0.01*growthrate!$F$3)^10 -> 677429.42 | T11: =O11*(1+0.01*growthrate!$F$3)^10 -> -23044.883 | U11: =P11*(1+0.01*growthrate!$F$3)^10 -> 674859.84 | V11: =Q11*(1+0.01*growthrate!$F$3)^10 -> 0 | W11: =R11*(1+0.01*growthrate!$F$3)^10 -> 0
A12: 0195 | B12: 종자 | C12: 백만원 | D12: 325776 | E12: 42514 | F12: 368290 | G12: 61422 | H12: 384345 | I12: =D12*(1+0.01*growthrate!E13)^2 -> 325776 | J12: =E12*(1+0.01*growthrate!$E$3)^2 -> 43798.986 | K12: =F12*(1+0.01*growthrate!$E$3)^2 -> 379421.57 | L12: =G12*(1+0.01*growthrate!$E$3)^2 -> 63278.48 | M12: =H12*(1+0.01*growthrate!$E$3)^2 -> 395961.83 | N12: =I12*(1+0.01*growthrate!$E$3)^5 -> 350953.27 | O12: =J12*(1+0.01*growthrate!$E$3)^5 -> 47183.947 | P12: =K12*(1+0.01*growthrate!$E$3)^5 -> 408744.78 | Q12: =L12*(1+0.01*growthrate!$E$3)^5 -> 68168.894 | R12: =M12*(1+0.01*growthrate!$E$3)^5 -> 426563.34 | S12: =N12*(1+0.01*growthrate!$F$3)^10 -> 376308.48 | T12: =O12*(1+0.01*growthrate!$F$3)^10 -> 50592.83 | U12: =P12*(1+0.01*growthrate!$F$3)^10 -> 438275.23 | V12: =Q12*(1+0.01*growthrate!$F$3)^10 -> 73093.87 | W12: =R12*(1+0.01*growthrate!$F$3)^10 -> 457381.12
A13: 0196 | B13: 기타식용작물 | C13: 백만원 | D13: 1308522 | E13: 212816 | F13: 1521338 | G13: 8166 | H13: 648944 | I13: =D13*(1+0.01*growthrate!E14)^2 -> 1308522 | J13: =E13*(1+0.01*growthrate!$E$3)^2 -> 219248.36 | K13: =F13*(1+0.01*growthrate!$E$3)^2 -> 1567320.4 | L13: =G13*(1+0.01*growthrate!$E$3)^2 -> 8412.8173 | M13: =H13*(1+0.01*growthrate!$E$3)^2 -> 668558.33 | N13: =I13*(1+0.01*growthrate!$E$3)^5 -> 1409649.8 | O13: =J13*(1+0.01*growthrate!$E$3)^5 -> 236192.75 | P13: =K13*(1+0.01*growthrate!$E$3)^5 -> 1688449.2 | Q13: =L13*(1+0.01*growthrate!$E$3)^5 -> 9062.9936 | R13: =M13*(1+0.01*growthrate!$E$3)^5 -> 720227.2 | S13: =N13*(1+0.01*growthrate!$F$3)^10 -> 1511492.3 | T13: =O13*(1+0.01*growthrate!$F$3)^10 -> 253256.89 | U13: =P13*(1+0.01*growthrate!$F$3)^10 -> 1810434.1 | V13: =Q13*(1+0.01*growthrate!$F$3)^10 -> 9717.7646 | W13: =R13*(1+0.01*growthrate!$F$3)^10 -> 772261.21
A14: 0199 | B14: 기타 비식용작물 | C14: 백만원 | D14: 505861 | E14: -15434 | F14: 490427 | G14: 195 | H14: 6128 | I14: =D14*(1+0.01*growthrate!E15)^2 -> 505861 | J14: =E14*(1+0.01*growthrate!$E$3)^2 -> -15900.493 | K14: =F14*(1+0.01*growthrate!$E$3)^2 -> 505250.16 | L14: =G14*(1+0.01*growthrate!$E$3)^2 -> 200.89387 | M14: =H14*(1+0.01*growthrate!$E$3)^2 -> 6313.2188 | N14: =I14*(1+0.01*growthrate!$E$3)^5 -> 544955.96 | O14: =J14*(1+0.01*growthrate!$E$3)^5 -> -17129.346 | P14: =K14*(1+0.01*growthrate!$E$3)^5 -> 544297.91 | Q14: =L14*(1+0.01*growthrate!$E$3)^5 -> 216.41976 | R14: =M14*(1+0.01*growthrate!$E$3)^5 -> 6801.1296 | S14: =N14*(1+0.01*growthrate!$F$3)^10 -> 584327.22 | T14: =O14*(1+0.01*growthrate!$F$3)^10 -> -18366.885 | U14: =P14*(1+0.01*growthrate!$F$3)^10 -> 583621.62 | V14: =Q14*(1+0.01*growthrate!$F$3)^10 -> 232.05536 | W14: =R14*(1+0.01*growthrate!$F$3)^10 -> 7292.4886
... A95: 1500 | B95: 인쇄 및 기록매체 복제 | C95: 백만원 | D95: 280312 | E95: 16323 | F95: 296635 | G95: 446879 | H95: 4348935 | I95: =D95*(1+0.01*growthrate!E96)^2 -> 280312 | J95: =E95*(1+0.01*growthrate!$E$3)^2 -> 16816.363 | K95: =F95*(1+0.01*growthrate!$E$3)^2 -> 305600.79 | L95: =G95*(1+0.01*growthrate!$E$3)^2 -> 460385.92 | M95: =H95*(1+0.01*growthrate!$E$3)^2 -> 4480381.6 | N95: =I95*(1+0.01*growthrate!$E$3)^5 -> 301975.63 | O95: =J95*(1+0.01*growthrate!$E$3)^5 -> 18115.999 | P95: =K95*(1+0.01*growthrate!$E$3)^5 -> 329218.85 | Q95: =L95*(1+0.01*growthrate!$E$3)^5 -> 495966.38 | R95: =M95*(1+0.01*growthrate!$E$3)^5 -> 4826643.4 | S95: =N95*(1+0.01*growthrate!$F$3)^10 -> 323792.37 | T95: =O95*(1+0.01*growthrate!$F$3)^10 -> 19424.819 | U95: =P95*(1+0.01*growthrate!$F$3)^10 -> 353003.81 | V95: =Q95*(1+0.01*growthrate!$F$3)^10 -> 531798.3 | W95: =R95*(1+0.01*growthrate!$F$3)^10 -> 5175352.3
A96: 1610 | B96: 석탄제품 | C96: 백만원 | D96: 200871 | E96: -6360 | F96: 194511 | G96: 84731 | H96: 55237 | I96: =D96*(1+0.01*growthrate!E97)^2 -> 200871 | J96: =E96*(1+0.01*growthrate!$E$3)^2 -> -6552.231 | K96: =F96*(1+0.01*growthrate!$E$3)^2 -> 200390.09 | L96: =G96*(1+0.01*growthrate!$E$3)^2 -> 87291.994 | M96: =H96*(1+0.01*growthrate!$E$3)^2 -> 56906.538 | N96: =I96*(1+0.01*growthrate!$E$3)^5 -> 216395.12 | O96: =J96*(1+0.01*growthrate!$E$3)^5-1780803.264 -> -1787861.9 | P96: =K96*(1+0.01*growthrate!$E$3)^5-1780803.264 -> -1564926.2 | Q96: =L96*(1+0.01*growthrate!$E$3)^5 -> 94038.269 | R96: =M96*(1+0.01*growthrate!$E$3)^5 -> 61304.503 | S96: =N96*(1+0.01*growthrate!$F$3)^10 -> 232028.94 | T96: =O96*(1+0.01*growthrate!$F$3)^10-633497.5693 -> -2550526.5 | U96: =P96*(1+0.01*growthrate!$F$3)^10-633497.5693 -> -2311484.5 | V96: =Q96*(1+0.01*growthrate!$F$3)^10 -> 100832.22 | W96: =R96*(1+0.01*growthrate!$F$3)^10 -> 65733.55
A97: 1621 | B97: 나프타 | C97: 백만원 | D97: 23136179 | E97: 57945 | F97: 23194124 | G97: 12527231 | H97: 1577347 | I97: =D97*(1+0.01*growthrate!E98)^2 -> 23136179 | J97: =E97*(1+0.01*growthrate!$E$3)^2 -> 59696.388 | K97: =F97*(1+0.01*growthrate!$E$3)^2 -> 23895166 | L97: =G97*(1+0.01*growthrate!$E$3)^2 -> 12905867 | M97: =H97*(1+0.01*growthrate!$E$3)^2 -> 1625022.3 | N97: =I97*(1+0.01*growthrate!$E$3)^5 -> 24924236 | O97: =J97*(1+0.01*growthrate!$E$3)^5 -> 64309.963 | P97: =K97*(1+0.01*growthrate!$E$3)^5 -> 25741881 | Q97: =L97*(1+0.01*growthrate!$E$3)^5 -> 13903284 | R97: =M97*(1+0.01*growthrate!$E$3)^5 -> 1750610.5 | S97: =N97*(1+0.01*growthrate!$F$3)^10 -> 26724929 | T97: =O97*(1+0.01*growthrate!$F$3)^10 -> 68956.144 | U97: =P97*(1+0.01*growthrate!$F$3)^10 -> 27601646 | V97: =Q97*(1+0.01*growthrate!$F$3)^10 -> 14907750 | W97: =R97*(1+0.01*growthrate!$F$3)^10 -> 1877086.3
A98: 1622 | B98: 휘발유 | C98: 백만원 | D98: 189538 | E98: 372167 | F98: 561705 | G98: 19388778 | H98: 10642292 | I98: =D98*(1+0.01*growthrate!E99)^2 -> 189538 | J98: =E98*(1+0.01*growthrate!$E$3)^2 -> 383415.75 | K98: =F98*(1+0.01*growthrate!$E$3)^2 -> 578682.53 | L98: =G98*(1+0.01*growthrate!$E$3)^2 -> 19974804 | M98: =H98*(1+0.01*growthrate!$E$3)^2 -> 10963955 | N98: =I98*(1+0.01*growthrate!$E$3)^5 -> 204186.26 | O98: =J98*(1+0.01*growthrate!$E$3)^5 -> 413047.65 | P98: =K98*(1+0.01*growthrate!$E$3)^5 -> 623405.44 | Q98: =L98*(1+0.01*growthrate!$E$3)^5 -> 21518537 | R98: =M98*(1+0.01*growthrate!$E$3)^5 -> 11811294 | S98: =N98*(1+0.01*growthrate!$F$3)^10 -> 218938.03 | T98: =O98*(1+0.01*growthrate!$F$3)^10 -> 442888.97 | U98: =P98*(1+0.01*growthrate!$F$3)^10 -> 668444.4 | V98: =Q98*(1+0.01*growthrate!$F$3)^10 -> 23073179 | W98: =R98*(1+0.01*growthrate!$F$3)^10 -> 12664620
A99: 1623 | B99: 제트유 | C99: 백만원 | D99: 3796295 | E99: 21342 | F99: 3817637 | G99: 15046080 | H99: 2001068 | I99: =D99*(1+0.01*growthrate!E100)^2 -> 3796295 | J99: =E99*(1+0.01*growthrate!$E$3)^2 -> 21987.062 | K99: =F99*(1+0.01*growthrate!$E$3)^2 -> 3933025.1 | L99: =G99*(1+0.01*growthrate!$E$3)^2 -> 15500848 | M99: =H99*(1+0.01*growthrate!$E$3)^2 -> 2061550.3 | N99: =I99*(1+0.01*growthrate!$E$3)^5 -> 4089687.9 | O99: =J99*(1+0.01*growthrate!$E$3)^5 -> 23686.31 | P99: =K99*(1+0.01*growthrate!$E$3)^5 -> 4236985 | Q99: =L99*(1+0.01*growthrate!$E$3)^5 -> 16698815 | R99: =M99*(1+0.01*growthrate!$E$3)^5 -> 2220875.1 | S99: =N99*(1+0.01*growthrate!$F$3)^10 -> 4385154.2 | T99: =O99*(1+0.01*growthrate!$F$3)^10 -> 25397.567 | U99: =P99*(1+0.01*growthrate!$F$3)^10 -> 4543093.1 | V99: =Q99*(1+0.01*growthrate!$F$3)^10 -> 17905249 | W99: =R99*(1+0.01*growthrate!$F$3)^10 -> 2381326
A100: 1624 | B100: 등유 | C100: 백만원 | D100: 9768 | E100: 3312 | F100: 13080 | G100: 4523322 | H100: 1228211 | I100: =D100*(1+0.01*growthrate!E101)^2 -> 9768 | J100: =E100*(1+0.01*growthrate!$E$3)^2 -> 3412.1052 | K100: =F100*(1+0.01*growthrate!$E$3)^2 -> 13475.343 | L100: =G100*(1+0.01*growthrate!$E$3)^2 -> 4660039.4 | M100: =H100*(1+0.01*growthrate!$E$3)^2 -> 1265333.7 | N100: =I100*(1+0.01*growthrate!$E$3)^5 -> 10522.91 | O100: =J100*(1+0.01*growthrate!$E$3)^5 -> 3675.8064 | P100: =K100*(1+0.01*growthrate!$E$3)^5 -> 14516.771 | Q100: =L100*(1+0.01*growthrate!$E$3)^5 -> 5020185.9 | R100: =M100*(1+0.01*growthrate!$E$3)^5 -> 1363123.7 | S100: =N100*(1+0.01*growthrate!$F$3)^10 -> 11283.155 | T100: =O100*(1+0.01*growthrate!$F$3)^10 -> 3941.3711 | U100: =P100*(1+0.01*growthrate!$F$3)^10 -> 15565.56 | V100: =Q100*(1+0.01*growthrate!$F$3)^10 -> 5382877.6 | W100: =R100*(1+0.01*growthrate!$F$3)^10 -> 1461604.9
A101: 1625 | B101: 경유 | C101: 백만원 | D101: 582997 | E101: 185669 | F101: 768666 | G101: 42282946 | H101: 12490442 | I101: =D101*(1+0.01*growthrate!E102)^2 -> 582997 | J101: =E101*(1+0.01*growthrate!$E$3)^2 -> 191280.85 | K101: =F101*(1+0.01*growthrate!$E$3)^2 -> 791898.93 | L101: =G101*(1+0.01*growthrate!$E$3)^2 -> 43560948 | M101: =H101*(1+0.01*growthrate!$E$3)^2 -> 12867966 | N101: =I101*(1+0.01*growthrate!$E$3)^5 -> 628053.34 | O101: =J101*(1+0.01*growthrate!$E$3)^5 -> 206063.8 | P101: =K101*(1+0.01*growthrate!$E$3)^5 -> 853100.05 | Q101: =L101*(1+0.01*growthrate!$E$3)^5 -> 46927513 | R101: =M101*(1+0.01*growthrate!$E$3)^5 -> 13862454 | S101: =N101*(1+0.01*growthrate!$F$3)^10 -> 673428.1 | T101: =O101*(1+0.01*growthrate!$F$3)^10 -> 220951.22 | U101: =P101*(1+0.01*growthrate!$F$3)^10 -> 914733.69 | V101: =Q101*(1+0.01*growthrate!$F$3)^10 -> 50317869 | W101: =R101*(1+0.01*growthrate!$F$3)^10 -> 14863970
A102: 1626 | B102: 중유 | C102: 백만원 | D102: 6984868 | E102: -42173 | F102: 6942695 | G102: 6084682 | H102: 1116909 | I102: =D102*(1+0.01*growthrate!E103)^2 -> 6984868 | J102: =E102*(1+0.01*growthrate!$E$3)^2 -> -43447.679 | K102: =F102*(1+0.01*growthrate!$E$3)^2 -> 7152538 | L102: =G102*(1+0.01*growthrate!$E$3)^2 -> 6268591.5 | M102: =H102*(1+0.01*growthrate!$E$3)^2 -> 1150667.6 | N102: =I102*(1+0.01*growthrate!$E$3)^5 -> 7524686.6 | O102: =J102*(1+0.01*growthrate!$E$3)^5 -> -46805.49 | P102: =K102*(1+0.01*growthrate!$E$3)^5 -> 7705314.7 | Q102: =L102*(1+0.01*growthrate!$E$3)^5 -> 6753053.4 | R102: =M102*(1+0.01*growthrate!$E$3)^5 -> 1239595.8 | S102: =N102*(1+0.01*growthrate!$F$3)^10 -> 8068320.1 | T102: =O102*(1+0.01*growthrate!$F$3)^10 -> -50187.03 | U102: =P102*(1+0.01*growthrate!$F$3)^10 -> 8261998 | V102: =Q102*(1+0.01*growthrate!$F$3)^10 -> 7240939 | W102: =R102*(1+0.01*growthrate!$F$3)^10 -> 1329152.4
A103: 1627 | B103: 액화석유가스 | C103: 백만원 | D103: 5433359 | E103: 1851423 | F103: 7284782 | G103: 2826854 | H103: 829539 | I103: =D103*(1+0.01*growthrate!E104)^2 -> 5433359 | J103: =E103*(1+0.01*growthrate!$E$3)^2 -> 1907382.3 | K103: =F103*(1+0.01*growthrate!$E$3)^2 -> 7504964.5 | L103: =G103*(1+0.01*growthrate!$E$3)^2 -> 2912295.7 | M103: =H103*(1+0.01*growthrate!$E$3)^2 -> 854611.82 | N103: =I103*(1+0.01*growthrate!$E$3)^5 -> 5853270.7 | O103: =J103*(1+0.01*growthrate!$E$3)^5 -> 2054792.4 | P103: =K103*(1+0.01*growthrate!$E$3)^5 -> 8084978.2 | Q103: =L103*(1+0.01*growthrate!$E$3)^5 -> 3137369.5 | R103: =M103*(1+0.01*growthrate!$E$3)^5 -> 920659.64 | S103: =N103*(1+0.01*growthrate!$F$3)^10 -> 6276150 | T103: =O103*(1+0.01*growthrate!$F$3)^10 -> 2203244.3 | U103: =P103*(1+0.01*growthrate!$F$3)^10 -> 8669091 | V103: =Q103*(1+0.01*growthrate!$F$3)^10 -> 3364034 | W103: =R103*(1+0.01*growthrate!$F$3)^10 -> 987174.23
A104: 1628 | B104: 정제혼합용 원료유 | C104: 백만원 | D104: 1234634 | E104: -11943 | F104: 1222691 | G104: 5500299 | H104: 982008 | I104: =D104*(1+0.01*growthrate!E105)^2 -> 1234634 | J104: =E104*(1+0.01*growthrate!$E$3)^2 -> -12303.977 | K104: =F104*(1+0.01*growthrate!$E$3)^2 -> 1259646.8 | L104: =G104*(1+0.01*growthrate!$E$3)^2 -> 5666545.5 | M104: =H104*(1+0.01*growthrate!$E$3)^2 -> 1011689.2 | N104: =I104*(1+0.01*growthrate!$E$3)^5 -> 1330051.5 | O104: =J104*(1+0.01*growthrate!$E$3)^5 -> -13254.878 | P104: =K104*(1+0.01*growthrate!$E$3)^5 -> 1356997.4 | Q104: =L104*(1+0.01*growthrate!$E$3)^5 -> 6104478.9 | R104: =M104*(1+0.01*growthrate!$E$3)^5 -> 1089876.6 | S104: =N104*(1+0.01*growthrate!$F$3)^10 -> 1426143.2 | T104: =O104*(1+0.01*growthrate!$F$3)^10 -> -14212.499 | U104: =P104*(1+0.01*growthrate!$F$3)^10 -> 1455035.9 | V104: =Q104*(1+0.01*growthrate!$F$3)^10 -> 6545507.1 | W104: =R104*(1+0.01*growthrate!$F$3)^10 -> 1168616.5
A105: 1631 | B105: 윤활유 및 그리스 | C105: 백만원 | D105: 890862 | E105: 41801 | F105: 932663 | G105: 1387065 | H105: 807917 | I105: =D105*(1+0.01*growthrate!E106)^2 -> 890862 | J105: =E105*(1+0.01*growthrate!$E$3)^2 -> 43064.435 | K105: =F105*(1+0.01*growthrate!$E$3)^2 -> 960852.74 | L105: =G105*(1+0.01*growthrate!$E$3)^2 -> 1428989 | M105: =H105*(1+0.01*growthrate!$E$3)^2 -> 832336.29 | N105: =I105*(1+0.01*growthrate!$E$3)^5 -> 959711.38 | O105: =J105*(1+0.01*growthrate!$E$3)^5 -> 46392.627 | P105: =K105*(1+0.01*growthrate!$E$3)^5 -> 1035111.3 | Q105: =L105*(1+0.01*growthrate!$E$3)^5 -> 1539427 | R105: =M105*(1+0.01*growthrate!$E$3)^5 -> 896662.57 | S105: =N105*(1+0.01*growthrate!$F$3)^10 -> 1029047.3 | T105: =O105*(1+0.01*growthrate!$F$3)^10 -> 49744.34 | U105: =P105*(1+0.01*growthrate!$F$3)^10 -> 1109894.6 | V105: =Q105*(1+0.01*growthrate!$F$3)^10 -> 1650645.5 | W105: =R105*(1+0.01*growthrate!$F$3)^10 -> 961443.46
A106: 1639 | B106: 기타 석유정제제품 | C106: 백만원 | D106: 188703 | E106: 1718 | F106: 190421 | G106: 4690479 | H106: 1258604 | I106: =D106*(1+0.01*growthrate!E107)^2 -> 188703 | J106: =E106*(1+0.01*growthrate!$E$3)^2 -> 1769.9265 | K106: =F106*(1+0.01*growthrate!$E$3)^2 -> 196176.47 | L106: =G106*(1+0.01*growthrate!$E$3)^2 -> 4832248.7 | M106: =H106*(1+0.01*growthrate!$E$3)^2 -> 1296645.3 | N106: =I106*(1+0.01*growthrate!$E$3)^5 -> 203286.72 | O106: =J106*(1+0.01*growthrate!$E$3)^5 -> 1906.7136 | P106: =K106*(1+0.01*growthrate!$E$3)^5 -> 211337.78 | Q106: =L106*(1+0.01*growthrate!$E$3)^5 -> 5205704.3 | R106: =M106*(1+0.01*growthrate!$E$3)^5 -> 1396855.2 | S106: =N106*(1+0.01*growthrate!$F$3)^10 -> 217973.51 | T106: =O106*(1+0.01*growthrate!$F$3)^10 -> 2044.4673 | U106: =P106*(1+0.01*growthrate!$F$3)^10 -> 226606.23 | V106: =Q106*(1+0.01*growthrate!$F$3)^10 -> 5581799 | W106: =R106*(1+0.01*growthrate!$F$3)^10 -> 1497773.4
A107: 1711 | B107: 지방족 기초유분 | C107: 백만원 | D107: 1208913 | E107: -30708 | F107: 1178205 | G107: 8142622 | H107: 679571 | I107: =D107*(1+0.01*growthrate!E108)^2 -> 1208913 | J107: =E107*(1+0.01*growthrate!$E$3)^2 -> -31636.149 | K107: =F107*(1+0.01*growthrate!$E$3)^2 -> 1213816.2 | L107: =G107*(1+0.01*growthrate!$E$3)^2 -> 8388732.7 | M107: =H107*(1+0.01*growthrate!$E$3)^2 -> 700111.03 | N107: =I107*(1+0.01*growthrate!$E$3)^5 -> 1302342.6 | O107: =J107*(1+0.01*growthrate!$E$3)^5 -> -34081.118 | P107: =K107*(1+0.01*growthrate!$E$3)^5 -> 1307624.8 | Q107: =L107*(1+0.01*growthrate!$E$3)^5 -> 9037047.6 | R107: =M107*(1+0.01*growthrate!$E$3)^5 -> 754218.42 | S107: =N107*(1+0.01*growthrate!$F$3)^10 -> 1396432.6 | T107: =O107*(1+0.01*growthrate!$F$3)^10 -> -36543.365 | U107: =P107*(1+0.01*growthrate!$F$3)^10 -> 1402096.4 | V107: =Q107*(1+0.01*growthrate!$F$3)^10 -> 9689944.2 | W107: =R107*(1+0.01*growthrate!$F$3)^10 -> 808708.19
A108: 1712 | B108: 방향족 기초유분 | C108: 백만원 | D108: 1221459 | E108: -1862 | F108: 1219597 | G108: 15919961 | H108: 2395584 | I108: =D108*(1+0.01*growthrate!E109)^2 -> 1221459 | J108: =E108*(1+0.01*growthrate!$E$3)^2 -> -1918.2789 | K108: =F108*(1+0.01*growthrate!$E$3)^2 -> 1256459.3 | L108: =G108*(1+0.01*growthrate!$E$3)^2 -> 16401142 | M108: =H108*(1+0.01*growthrate!$E$3)^2 -> 2467990.5 | N108: =I108*(1+0.01*growthrate!$E$3)^5 -> 1315858.2 | O108: =J108*(1+0.01*growthrate!$E$3)^5 -> -2066.5312 | P108: =K108*(1+0.01*growthrate!$E$3)^5 -> 1353563.5 | Q108: =L108*(1+0.01*growthrate!$E$3)^5 -> 17668688 | R108: =M108*(1+0.01*growthrate!$E$3)^5 -> 2658726.7 | S108: =N108*(1+0.01*growthrate!$F$3)^10 -> 1410924.6 | T108: =O108*(1+0.01*growthrate!$F$3)^10 -> -2215.8312 | U108: =P108*(1+0.01*growthrate!$F$3)^10 -> 1451354 | V108: =Q108*(1+0.01*growthrate!$F$3)^10 -> 18945192 | W108: =R108*(1+0.01*growthrate!$F$3)^10 -> 2850810.9
... A273: 4505 | B273: 신에너지 | C273: 백만원 | D273: 824 | E273: 400 | F273: 1224 | G273: 41205 | H273: 896226 | I273: =D273*(1+0.01*growthrate!E274)^2 -> 824 | J273: =E273*(1+0.01*growthrate!$E$3)^2 -> 412.09 | K273: =F273*(1+0.01*growthrate!$E$3)^2 -> 1260.9954 | L273: =G273*(1+0.01*growthrate!$E$3)^2 -> 42450.421 | M273: =H273*(1+0.01*growthrate!$E$3)^2 -> 923314.43 | N273: =I273*(1+0.01*growthrate!$E$3)^5 -> 887.68202 | O273: =J273*(1+0.01*growthrate!$E$3)^5 -> 443.93797 | P273: =K273*(1+0.01*growthrate!$E$3)^5 -> 1358.4502 | Q273: =L273*(1+0.01*growthrate!$E$3)^5 -> 45731.16 | R273: =M273*(1+0.01*growthrate!$E$3)^5 -> 994671.87 | S273: =N273*(1+0.01*growthrate!$F$3)^10 -> 951.81409 | T273: =O273*(1+0.01*growthrate!$F$3)^10 -> 476.011 | U273: =P273*(1+0.01*growthrate!$F$3)^10 -> 1456.5937 | V273: =Q273*(1+0.01*growthrate!$F$3)^10 -> 49035.084 | W273: =R273*(1+0.01*growthrate!$F$3)^10 -> 1066533.6
A274: 4506 | B274: 재생에너지 | C274: 백만원 | D274: 4136 | E274: 1686 | F274: 5822 | G274: 753149 | H274: 2002656 | I274: =D274*(1+0.01*growthrate!E275)^2 -> 4136 | J274: =E274*(1+0.01*growthrate!$E$3)^2+966657.038814344 -> 968394 | K274: =F274*(1+0.01*growthrate!$E$3)^2+966657.038814344 -> 972655.01 | L274: =G274*(1+0.01*growthrate!$E$3)^2 -> 775912.93 | M274: =H274*(1+0.01*growthrate!$E$3)^2 -> 2063186.3 | N274: =I274*(1+0.01*growthrate!$E$3)^5 -> 4455.6466 | O274: =J274*(1+0.01*growthrate!$E$3)^5+11234183.3223552 -> 12277419 | P274: =K274*(1+0.01*growthrate!$E$3)^5+11234183.3223552 -> 12282009 | Q274: =L274*(1+0.01*growthrate!$E$3)^5 -> 835878.59 | R274: =M274*(1+0.01*growthrate!$E$3)^5 -> 2222637.6 | S274: =N274*(1+0.01*growthrate!$F$3)^10 -> 4777.5523 | T274: =O274*(1+0.01*growthrate!$F$3)^10+39575034 -> 52739455 | U274: =P274*(1+0.01*growthrate!$F$3)^10+39575034 -> 52744377 | V274: =Q274*(1+0.01*growthrate!$F$3)^10 -> 896268.03 | W274: =R274*(1+0.01*growthrate!$F$3)^10 -> 2383215.7
A275: 4610 | B275: 도시가스 | C275: 백만원 | D275: 35118 | E275: 36386 | F275: 71504 | G275: 38485754 | H275: 5764818 | I275: =D275*(1+0.01*growthrate!E276)^2 -> 35118 | J275: =E275*(1+0.01*growthrate!$E$3)^2 -> 37485.767 | K275: =F275*(1+0.01*growthrate!$E$3)^2 -> 73665.208 | L275: =G275*(1+0.01*growthrate!$E$3)^2 -> 39648986 | M275: =H275*(1+0.01*growthrate!$E$3)^2 -> 5939059.6 | N275: =I275*(1+0.01*growthrate!$E$3)^5 -> 37832.06 | O275: =J275*(1+0.01*growthrate!$E$3)^5 -> 40382.817 | P275: =K275*(1+0.01*growthrate!$E$3)^5 -> 79358.351 | Q275: =L275*(1+0.01*growthrate!$E$3)^5 -> 42713218 | R275: =M275*(1+0.01*growthrate!$E$3)^5 -> 6398053.9 | S275: =N275*(1+0.01*growthrate!$F$3)^10 -> 40565.3 | T275: =O275*(1+0.01*growthrate!$F$3)^10 -> 43300.341 | U275: =P275*(1+0.01*growthrate!$F$3)^10 -> 85091.727 | V275: =Q275*(1+0.01*growthrate!$F$3)^10 -> 45799106 | W275: =R275*(1+0.01*growthrate!$F$3)^10 -> 6860292
A276: 4620 | B276: 증기 및 온수 공급 | C276: 백만원 | D276: 7352 | E276: 3848 | F276: 11200 | G276: 220906 | H276: 2589571 | I276: =D276*(1+0.01*growthrate!E277)^2 -> 7352 | J276: =E276*(1+0.01*growthrate!$E$3)^2 -> 3964.3058 | K276: =F276*(1+0.01*growthrate!$E$3)^2 -> 11538.52 | L276: =G276*(1+0.01*growthrate!$E$3)^2 -> 227582.88 | M276: =H276*(1+0.01*growthrate!$E$3)^2 -> 2667840.8 | N276: =I276*(1+0.01*growthrate!$E$3)^5 -> 7920.192 | O276: =J276*(1+0.01*growthrate!$E$3)^5 -> 4270.6832 | P276: =K276*(1+0.01*growthrate!$E$3)^5 -> 12430.263 | Q276: =L276*(1+0.01*growthrate!$E$3)^5 -> 245171.4 | R276: =M276*(1+0.01*growthrate!$E$3)^5 -> 2874022.2 | S276: =N276*(1+0.01*growthrate!$F$3)^10 -> 8492.3995 | T276: =O276*(1+0.01*growthrate!$F$3)^10 -> 4579.2259 | U276: =P276*(1+0.01*growthrate!$F$3)^10 -> 13328.308 | V276: =Q276*(1+0.01*growthrate!$F$3)^10 -> 262884.22 | W276: =R276*(1+0.01*growthrate!$F$3)^10 -> 3081660.7
A277: 4700 | B277: 수도 | C277: 백만원 | D277: 8967 | E277: 5656 | F277: 14623 | G277: 223035 | H277: 2588910 | I277: =D277*(1+0.01*growthrate!E278)^2 -> 8967 | J277: =E277*(1+0.01*growthrate!$E$3)^2 -> 5826.9526 | K277: =F277*(1+0.01*growthrate!$E$3)^2 -> 15064.98 | L277: =G277*(1+0.01*growthrate!$E$3)^2 -> 229776.23 | M277: =H277*(1+0.01*growthrate!$E$3)^2 -> 2667159.8 | N277: =I277*(1+0.01*growthrate!$E$3)^5 -> 9660.0057 | O277: =J277*(1+0.01*growthrate!$E$3)^5 -> 6277.2828 | P277: =K277*(1+0.01*growthrate!$E$3)^5 -> 16229.262 | Q277: =L277*(1+0.01*growthrate!$E$3)^5 -> 247534.26 | R277: =M277*(1+0.01*growthrate!$E$3)^5 -> 2873288.6 | S277: =N277*(1+0.01*growthrate!$F$3)^10 -> 10357.909 | T277: =O277*(1+0.01*growthrate!$F$3)^10 -> 6730.7956 | U277: =P277*(1+0.01*growthrate!$F$3)^10 -> 17401.772 | V277: =Q277*(1+0.01*growthrate!$F$3)^10 -> 265417.79 | W277: =R277*(1+0.01*growthrate!$F$3)^10 -> 3080874.1
A278: 4801 | B278: 하수,폐수 및 분뇨처리(국공립) | C278: 백만원 | D278: 3483 | E278: 4455 | F278: 7938 | G278: 32619 | H278: 2211300 | I278: =D278*(1+0.01*growthrate!E279)^2 -> 3483 | J278: =E278*(1+0.01*growthrate!$E$3)^2 -> 4589.6524 | K278: =F278*(1+0.01*growthrate!$E$3)^2 -> 8177.926 | L278: =G278*(1+0.01*growthrate!$E$3)^2 -> 33604.909 | M278: =H278*(1+0.01*growthrate!$E$3)^2 -> 2278136.5 | N278: =I278*(1+0.01*growthrate!$E$3)^5 -> 3752.1802 | O278: =J278*(1+0.01*growthrate!$E$3)^5 -> 4944.3591 | P278: =K278*(1+0.01*growthrate!$E$3)^5 -> 8809.9489 | Q278: =L278*(1+0.01*growthrate!$E$3)^5 -> 36202.031 | R278: =M278*(1+0.01*growthrate!$E$3)^5 -> 2454200.1 | S278: =N278*(1+0.01*growthrate!$F$3)^10 -> 4023.2627 | T278: =O278*(1+0.01*growthrate!$F$3)^10 -> 5301.5726 | U278: =P278*(1+0.01*growthrate!$F$3)^10 -> 9446.4384 | V278: =Q278*(1+0.01*growthrate!$F$3)^10 -> 38817.507 | W278: =R278*(1+0.01*growthrate!$F$3)^10 -> 2631507.8
A279: 4802 | B279: 하수,폐수 및 분뇨처리(산업) | C279: 백만원 | D279: 1930 | E279: 83 | F279: 2013 | G279: 16170 | H279: 1949720 | I279: =D279*(1+0.01*growthrate!E280)^2 -> 1930 | J279: =E279*(1+0.01*growthrate!$E$3)^2 -> 85.508675 | K279: =F279*(1+0.01*growthrate!$E$3)^2 -> 2073.8429 | L279: =G279*(1+0.01*growthrate!$E$3)^2 -> 16658.738 | M279: =H279*(1+0.01*growthrate!$E$3)^2 -> 2008650.3 | N279: =I279*(1+0.01*growthrate!$E$3)^5 -> 2079.1581 | O279: =J279*(1+0.01*growthrate!$E$3)^5 -> 92.117128 | P279: =K279*(1+0.01*growthrate!$E$3)^5 -> 2234.1178 | Q279: =L279*(1+0.01*growthrate!$E$3)^5 -> 17946.192 | R279: =M279*(1+0.01*growthrate!$E$3)^5 -> 2163886.8 | S279: =N279*(1+0.01*growthrate!$F$3)^10 -> 2229.3704 | T279: =O279*(1+0.01*growthrate!$F$3)^10 -> 98.772283 | U279: =P279*(1+0.01*growthrate!$F$3)^10 -> 2395.5254 | V279: =Q279*(1+0.01*growthrate!$F$3)^10 -> 19242.745 | W279: =R279*(1+0.01*growthrate!$F$3)^10 -> 2320220.4
A280: 4911 | B280: 폐기물 수집, 운반 및 처리(국공립) | C280: 백만원 | D280: 0 | E280: 0 | F280: 0 | G280: 3 | H280: 2215 | I280: =D280*(1+0.01*growthrate!E281)^2 -> 0 | J280: =E280*(1+0.01*growthrate!$E$3)^2 -> 0 | K280: =F280*(1+0.01*growthrate!$E$3)^2 -> 0 | L280: =G280*(1+0.01*growthrate!$E$3)^2 -> 3.090675 | M280: =H280*(1+0.01*growthrate!$E$3)^2 -> 2281.9484 | N280: =I280*(1+0.01*growthrate!$E$3)^5 -> 0 | O280: =J280*(1+0.01*growthrate!$E$3)^5 -> 0 | P280: =K280*(1+0.01*growthrate!$E$3)^5 -> 0 | Q280: =L280*(1+0.01*growthrate!$E$3)^5 -> 3.3295347 | R280: =M280*(1+0.01*growthrate!$E$3)^5 -> 2458.3065 | S280: =N280*(1+0.01*growthrate!$F$3)^10 -> 0 | T280: =O280*(1+0.01*growthrate!$F$3)^10 -> 0 | U280: =P280*(1+0.01*growthrate!$F$3)^10 -> 0 | V280: =Q280*(1+0.01*growthrate!$F$3)^10 -> 3.5700825 | W280: =R280*(1+0.01*growthrate!$F$3)^10 -> 2635.9109
A281: 4912 | B281: 폐기물 수집, 운반 및 처리(산업) | C281: 백만원 | D281: 136728 | E281: 31053 | F281: 167781 | G281: 184719 | H281: 6501889 | I281: =D281*(1+0.01*growthrate!E282)^2 -> 136728 | J281: =E281*(1+0.01*growthrate!$E$3)^2 -> 31991.577 | K281: =F281*(1+0.01*growthrate!$E$3)^2 -> 172852.18 | L281: =G281*(1+0.01*growthrate!$E$3)^2 -> 190302.13 | M281: =H281*(1+0.01*growthrate!$E$3)^2 -> 6698408.6 | N281: =I281*(1+0.01*growthrate!$E$3)^5 -> 147294.89 | O281: =J281*(1+0.01*growthrate!$E$3)^5 -> 34464.014 | P281: =K281*(1+0.01*growthrate!$E$3)^5 -> 186210.89 | Q281: =L281*(1+0.01*growthrate!$E$3)^5 -> 205009.44 | R281: =M281*(1+0.01*growthrate!$E$3)^5 -> 7216088.4 | S281: =N281*(1+0.01*growthrate!$F$3)^10 -> 157936.45 | T281: =O281*(1+0.01*growthrate!$F$3)^10 -> 36953.924 | U281: =P281*(1+0.01*growthrate!$F$3)^10 -> 199664.01 | V281: =Q281*(1+0.01*growthrate!$F$3)^10 -> 219820.69 | W281: =R281*(1+0.01*growthrate!$F$3)^10 -> 7737426.8
A282: 4920 | B282: 자원재활용서비스 | C282: 백만원 | D282: 0 | E282: 0 | F282: 0 | G282: 348511 | H282: 5512792 | I282: =D282*(1+0.01*growthrate!E283)^2 -> 0 | J282: =E282*(1+0.01*growthrate!$E$3)^2 -> 0 | K282: =F282*(1+0.01*growthrate!$E$3)^2 -> 0 | L282: =G282*(1+0.01*growthrate!$E$3)^2 -> 359044.74 | M282: =H282*(1+0.01*growthrate!$E$3)^2 -> 5679416.1 | N282: =I282*(1+0.01*growthrate!$E$3)^5 -> 0 | O282: =J282*(1+0.01*growthrate!$E$3)^5 -> 0 | P282: =K282*(1+0.01*growthrate!$E$3)^5 -> 0 | Q282: =L282*(1+0.01*growthrate!$E$3)^5 -> 386793.16 | R282: =M282*(1+0.01*growthrate!$E$3)^5 -> 6118344.2 | S282: =N282*(1+0.01*growthrate!$F$3)^10 -> 0 | T282: =O282*(1+0.01*growthrate!$F$3)^10 -> 0 | U282: =P282*(1+0.01*growthrate!$F$3)^10 -> 0 | V282: =Q282*(1+0.01*growthrate!$F$3)^10 -> 414737.68 | W282: =R282*(1+0.01*growthrate!$F$3)^10 -> 6560374.1
A283: 5010 | B283: 주거용 건물 | C283: 백만원 | D283: 0 | E283: 0 | F283: 0 | G283: 4724733 | H283: 42253964 | I283: =D283*(1+0.01*growthrate!E284)^2 -> 0 | J283: =E283*(1+0.01*growthrate!$E$3)^2 -> 0 | K283: =F283*(1+0.01*growthrate!$E$3)^2 -> 0 | L283: =G283*(1+0.01*growthrate!$E$3)^2 -> 4867538.1 | M283: =H283*(1+0.01*growthrate!$E$3)^2 -> 43531090 | N283: =I283*(1+0.01*growthrate!$E$3)^5 -> 0 | O283: =J283*(1+0.01*growthrate!$E$3)^5 -> 0 | P283: =K283*(1+0.01*growthrate!$E$3)^5 -> 0 | Q283: =L283*(1+0.01*growthrate!$E$3)^5 -> 5243720.9 | R283: =M283*(1+0.01*growthrate!$E$3)^5 -> 46895347 | S283: =N283*(1+0.01*growthrate!$F$3)^10 -> 0 | T283: =O283*(1+0.01*growthrate!$F$3)^10 -> 0 | U283: =P283*(1+0.01*growthrate!$F$3)^10 -> 0 | V283: =Q283*(1+0.01*growthrate!$F$3)^10 -> 5622562.2 | W283: =R283*(1+0.01*growthrate!$F$3)^10 -> 50283380
A284: 5020 | B284: 비주거용 건물 | C284: 백만원 | D284: 0 | E284: 0 | F284: 0 | G284: 4757344 | H284: 51551759 | I284: =D284*(1+0.01*growthrate!E285)^2 -> 0 | J284: =E284*(1+0.01*growthrate!$E$3)^2 -> 0 | K284: =F284*(1+0.01*growthrate!$E$3)^2 -> 0 | L284: =G284*(1+0.01*growthrate!$E$3)^2 -> 4901134.7 | M284: =H284*(1+0.01*growthrate!$E$3)^2 -> 53109911 | N284: =I284*(1+0.01*growthrate!$E$3)^5 -> 0 | O284: =J284*(1+0.01*growthrate!$E$3)^5 -> 0 | P284: =K284*(1+0.01*growthrate!$E$3)^5 -> 0 | Q284: =L284*(1+0.01*growthrate!$E$3)^5 -> 5279914 | R284: =M284*(1+0.01*growthrate!$E$3)^5 -> 57214457 | S284: =N284*(1+0.01*growthrate!$F$3)^10 -> 0 | T284: =O284*(1+0.01*growthrate!$F$3)^10 -> 0 | U284: =P284*(1+0.01*growthrate!$F$3)^10 -> 0 | V284: =Q284*(1+0.01*growthrate!$F$3)^10 -> 5661370.2 | W284: =R284*(1+0.01*growthrate!$F$3)^10 -> 61348011
...

Sheet topdown
A1: code | B1: sector | C1: unit | D1: 2023 | E1: 2023 | F1: 2023 | G1: 2023 | H1: 2025 | I1: 2025 | J1: 2025 | K1: 2025 | L1: 2030 | M1: 2030 | N1: 2030 | O1: 2030 | P1: 2040 | Q1: 2040 | R1: 2040 | S1: 2040
A2: code | B2: sector | C2: 백만원 | D2: 중간수요계 | E2: 최종수요계 | F2: 총수요계 | G2: 중간투입계(행합) | H2: 중간수요계 | I2: 최종수요계 | J2: 총수요계 | K2: 중간투입계(행합) | L2: 중간수요계 | M2: 최종수요계 | N2: 총수요계 | O2: 중간투입계(행합) | P2: 중간수요계 | Q2: 최종수요계 | R2: 총수요계 | S2: 중간투입계(행합)
A3: 0111 | B3: 벼 | C3: 백만원 | D3: 0 | E3: 0 | F3: 0 | G3: 248598 | H3: =D3*(1+0.01*growthrate!$E$3)^2 -> 0 | I3: =E3*(1+0.01*growthrate!$E$3)^2 -> 0 | J3: =F3*(1+0.01*growthrate!$E$3)^2 -> 0 | K3: =G3*(1+0.01*growthrate!$E$3)^2 -> 256111.87 | L3: =H3*(1+0.01*growthrate!$E$3)^5 -> 0 | M3: =I3*(1+0.01*growthrate!$E$3)^5 -> 0 | N3: =J3*(1+0.01*growthrate!$E$3)^5 -> 0 | O3: =K3*(1+0.01*growthrate!$E$3)^5 -> 275905.23 | P3: =L3*(1+0.01*growthrate!$F$3)^10 -> 0 | Q3: =M3*(1+0.01*growthrate!$F$3)^10 -> 0 | R3: =N3*(1+0.01*growthrate!$F$3)^10 -> 0 | S3: =O3*(1+0.01*growthrate!$F$3)^10 -> 295838.46
A4: 0112 | B4: 맥류 및 잡곡 | C4: 백만원 | D4: 6778410 | E4: 102197 | F4: 6880607 | G4: 11736 | H4: =D4*(1+0.01*growthrate!E4)^2 -> 7010834.9 | I4: =E4*(1+0.01*growthrate!$E$3)^2 -> 105285.9 | J4: =F4*(1+0.01*growthrate!$E$3)^2 -> 7088573.3 | K4: =G4*(1+0.01*growthrate!$E$3)^2 -> 12090.721 | L4: =H4*(1+0.01*growthrate!$E$3)^5 -> 7552660.3 | M4: =I4*(1+0.01*growthrate!$E$3)^5 -> 113422.82 | N4: =J4*(1+0.01*growthrate!$E$3)^5 -> 7636406.7 | O4: =K4*(1+0.01*growthrate!$E$3)^5 -> 13025.14 | P4: =L4*(1+0.01*growthrate!$F$3)^10 -> 8098314.8 | Q4: =M4*(1+0.01*growthrate!$F$3)^10 -> 121617.24 | R4: =N4*(1+0.01*growthrate!$F$3)^10 -> 8188111.6 | S4: =O4*(1+0.01*growthrate!$F$3)^10 -> 13966.163
A5: 0113 | B5: 콩류 | C5: 백만원 | D5: 1047612 | E5: 280198 | F5: 1327810 | G5: 3157 | H5: =D5*(1+0.01*growthrate!E5)^2 -> 1047612 | I5: =E5*(1+0.01*growthrate!$E$3)^2 -> 288666.98 | J5: =F5*(1+0.01*growthrate!$E$3)^2 -> 1367943.1 | K5: =G5*(1+0.01*growthrate!$E$3)^2 -> 3252.4203 | L5: =H5*(1+0.01*growthrate!$E$3)^5 -> 1128575.6 | M5: =I5*(1+0.01*growthrate!$E$3)^5 -> 310976.32 | N5: =J5*(1+0.01*growthrate!$E$3)^5 -> 1473663.2 | O5: =K5*(1+0.01*growthrate!$E$3)^5 -> 3503.7804 | P5: =L5*(1+0.01*growthrate!$F$3)^10 -> 1210111.5 | Q5: =M5*(1+0.01*growthrate!$F$3)^10 -> 333443.33 | R5: =N5*(1+0.01*growthrate!$F$3)^10 -> 1580130.4 | S5: =O5*(1+0.01*growthrate!$F$3)^10 -> 3756.9169
A6: 0114 | B6: 감자류 | C6: 백만원 | D6: 43309 | E6: 5701 | F6: 49010 | G6: 8846 | H6: =D6*(1+0.01*growthrate!E6)^2 -> 43309 | I6: =E6*(1+0.01*growthrate!$E$3)^2 -> 5873.3127 | J6: =F6*(1+0.01*growthrate!$E$3)^2 -> 50491.327 | K6: =G6*(1+0.01*growthrate!$E$3)^2 -> 9113.3703 | L6: =H6*(1+0.01*growthrate!$E$3)^5 -> 46656.093 | M6: =I6*(1+0.01*growthrate!$E$3)^5 -> 6327.2258 | N6: =J6*(1+0.01*growthrate!$E$3)^5 -> 54393.499 | O6: =K6*(1+0.01*growthrate!$E$3)^5 -> 9817.6881 | P6: =L6*(1+0.01*growthrate!$F$3)^10 -> 50026.84 | Q6: =M6*(1+0.01*growthrate!$F$3)^10 -> 6784.3468 | R6: =N6*(1+0.01*growthrate!$F$3)^10 -> 58323.248 | S6: =O6*(1+0.01*growthrate!$F$3)^10 -> 10526.983
A7: 0121 | B7: 채소 | C7: 백만원 | D7: 192086 | E7: 347759 | F7: 539845 | G7: 573328 | H7: =D7*(1+0.01*growthrate!E7)^2 -> 192086 | I7: =E7*(1+0.01*growthrate!$E$3)^2 -> 358270.02 | J7: =F7*(1+0.01*growthrate!$E$3)^2 -> 556161.82 | K7: =G7*(1+0.01*growthrate!$E$3)^2 -> 590656.84 | L7: =H7*(1+0.01*growthrate!$E$3)^5 -> 206931.18 | M7: =I7*(1+0.01*growthrate!$E$3)^5 -> 385958.56 | N7: =J7*(1+0.01*growthrate!$E$3)^5 -> 599144.23 | O7: =K7*(1+0.01*growthrate!$E$3)^5 -> 636305.16 | P7: =L7*(1+0.01*growthrate!$F$3)^10 -> 221881.26 | Q7: =M7*(1+0.01*growthrate!$F$3)^10 -> 413842.78 | R7: =N7*(1+0.01*growthrate!$F$3)^10 -> 642430.4 | S7: =O7*(1+0.01*growthrate!$F$3)^10 -> 682276.09
A8: 0122 | B8: 과실 | C8: 백만원 | D8: 166506 | E8: 1630308 | F8: 1796814 | G8: 221302 | H8: =D8*(1+0.01*growthrate!E8)^2 -> 166506 | I8: =E8*(1+0.01*growthrate!$E$3)^2 -> 1679584.1 | J8: =F8*(1+0.01*growthrate!$E$3)^2 -> 1851122.7 | K8: =G8*(1+0.01*growthrate!$E$3)^2 -> 227990.85 | L8: =H8*(1+0.01*growthrate!$E$3)^5 -> 179374.25 | M8: =I8*(1+0.01*growthrate!$E$3)^5 -> 1809389 | N8: =J8*(1+0.01*growthrate!$E$3)^5 -> 1994184.9 | O8: =K8*(1+0.01*growthrate!$E$3)^5 -> 245610.9 | P8: =L8*(1+0.01*growthrate!$F$3)^10 -> 192333.44 | Q8: =M8*(1+0.01*growthrate!$F$3)^10 -> 1940111.4 | R8: =N8*(1+0.01*growthrate!$F$3)^10 -> 2138258.1 | S8: =O8*(1+0.01*growthrate!$F$3)^10 -> 263355.47
A9: 0191 | B9: 화훼작물 | C9: 백만원 | D9: 40441 | E9: 131257 | F9: 171698 | G9: 85072 | H9: =D9*(1+0.01*growthrate!E9)^2 -> 40441 | I9: =E9*(1+0.01*growthrate!$E$3)^2 -> 135224.24 | J9: =F9*(1+0.01*growthrate!$E$3)^2 -> 176887.57 | K9: =G9*(1+0.01*growthrate!$E$3)^2 -> 87643.301 | L9: =H9*(1+0.01*growthrate!$E$3)^5 -> 43566.442 | M9: =I9*(1+0.01*growthrate!$E$3)^5 -> 145674.91 | N9: =J9*(1+0.01*growthrate!$E$3)^5 -> 190558.15 | O9: =K9*(1+0.01*growthrate!$E$3)^5 -> 94416.726 | P9: =L9*(1+0.01*growthrate!$F$3)^10 -> 46713.973 | Q9: =M9*(1+0.01*growthrate!$F$3)^10 -> 156199.44 | R9: =N9*(1+0.01*growthrate!$F$3)^10 -> 204325.34 | S9: =O9*(1+0.01*growthrate!$F$3)^10 -> 101238.02
A10: 0192 | B10: 약용작물 | C10: 백만원 | D10: 139519 | E10: 98856 | F10: 238375 | G10: 27806 | H10: =D10*(1+0.01*growthrate!E10)^2 -> 139519 | I10: =E10*(1+0.01*growthrate!$E$3)^2 -> 101843.92 | J10: =F10*(1+0.01*growthrate!$E$3)^2 -> 245579.88 | K10: =G10*(1+0.01*growthrate!$E$3)^2 -> 28646.436 | L10: =H10*(1+0.01*growthrate!$E$3)^5 -> 150301.59 | M10: =I10*(1+0.01*growthrate!$E$3)^5 -> 109714.83 | N10: =J10*(1+0.01*growthrate!$E$3)^5 -> 264559.28 | O10: =K10*(1+0.01*growthrate!$E$3)^5 -> 30860.348 | P10: =L10*(1+0.01*growthrate!$F$3)^10 -> 161160.38 | Q10: =M10*(1+0.01*growthrate!$F$3)^10 -> 117641.36 | R10: =N10*(1+0.01*growthrate!$F$3)^10 -> 283672.81 | S10: =O10*(1+0.01*growthrate!$F$3)^10 -> 33089.905
A11: 0193 | B11: 잎담배 | C11: 백만원 | D11: 382739 | E11: 22142 | F11: 404881 | G11: 666 | H11: =D11*(1+0.01*growthrate!E11)^2 -> 382739 | I11: =E11*(1+0.01*growthrate!$E$3)^2 -> 22811.242 | J11: =F11*(1+0.01*growthrate!$E$3)^2 -> 417118.53 | K11: =G11*(1+0.01*growthrate!$E$3)^2 -> 686.12985 | L11: =H11*(1+0.01*growthrate!$E$3)^5 -> 412318.6 | M11: =I11*(1+0.01*growthrate!$E$3)^5 -> 24574.186 | N11: =J11*(1+0.01*growthrate!$E$3)^5 -> 449355.12 | O11: =K11*(1+0.01*growthrate!$E$3)^5 -> 739.15671 | P11: =L11*(1+0.01*growthrate!$F$3)^10 -> 442107.25 | Q11: =M11*(1+0.01*growthrate!$F$3)^10 -> 26349.589 | R11: =N11*(1+0.01*growthrate!$F$3)^10 -> 481819.53 | S11: =O11*(1+0.01*growthrate!$F$3)^10 -> 792.55832
A12: 0194 | B12: 천연고무 | C12: 백만원 | D12: 586461 | E12: -19365 | F12: 567096 | G12: 0 | H12: =D12*(1+0.01*growthrate!E12)^2 -> 586461 | I12: =E12*(1+0.01*growthrate!$E$3)^2 -> -19950.307 | J12: =F12*(1+0.01*growthrate!$E$3)^2 -> 584236.48 | K12: =G12*(1+0.01*growthrate!$E$3)^2 -> 0 | L12: =H12*(1+0.01*growthrate!$E$3)^5 -> 631785.05 | M12: =I12*(1+0.01*growthrate!$E$3)^5 -> -21492.147 | N12: =J12*(1+0.01*growthrate!$E$3)^5 -> 629388.61 | O12: =K12*(1+0.01*growthrate!$E$3)^5 -> 0 | P12: =L12*(1+0.01*growthrate!$F$3)^10 -> 677429.42 | Q12: =M12*(1+0.01*growthrate!$F$3)^10 -> -23044.883 | R12: =N12*(1+0.01*growthrate!$F$3)^10 -> 674859.84 | S12: =O12*(1+0.01*growthrate!$F$3)^10 -> 0
A13: 0195 | B13: 종자 | C13: 백만원 | D13: 325776 | E13: 42514 | F13: 368290 | G13: 61422 | H13: =D13*(1+0.01*growthrate!E13)^2 -> 325776 | I13: =E13*(1+0.01*growthrate!$E$3)^2 -> 43798.986 | J13: =F13*(1+0.01*growthrate!$E$3)^2 -> 379421.57 | K13: =G13*(1+0.01*growthrate!$E$3)^2 -> 63278.48 | L13: =H13*(1+0.01*growthrate!$E$3)^5 -> 350953.27 | M13: =I13*(1+0.01*growthrate!$E$3)^5 -> 47183.947 | N13: =J13*(1+0.01*growthrate!$E$3)^5 -> 408744.78 | O13: =K13*(1+0.01*growthrate!$E$3)^5 -> 68168.894 | P13: =L13*(1+0.01*growthrate!$F$3)^10 -> 376308.48 | Q13: =M13*(1+0.01*growthrate!$F$3)^10 -> 50592.83 | R13: =N13*(1+0.01*growthrate!$F$3)^10 -> 438275.23 | S13: =O13*(1+0.01*growthrate!$F$3)^10 -> 73093.87
A14: 0196 | B14: 기타식용작물 | C14: 백만원 | D14: 1308522 | E14: 212816 | F14: 1521338 | G14: 8166 | H14: =D14*(1+0.01*growthrate!E14)^2 -> 1308522 | I14: =E14*(1+0.01*growthrate!$E$3)^2 -> 219248.36 | J14: =F14*(1+0.01*growthrate!$E$3)^2 -> 1567320.4 | K14: =G14*(1+0.01*growthrate!$E$3)^2 -> 8412.8173 | L14: =H14*(1+0.01*growthrate!$E$3)^5 -> 1409649.8 | M14: =I14*(1+0.01*growthrate!$E$3)^5 -> 236192.75 | N14: =J14*(1+0.01*growthrate!$E$3)^5 -> 1688449.2 | O14: =K14*(1+0.01*growthrate!$E$3)^5 -> 9062.9936 | P14: =L14*(1+0.01*growthrate!$F$3)^10 -> 1511492.3 | Q14: =M14*(1+0.01*growthrate!$F$3)^10 -> 253256.89 | R14: =N14*(1+0.01*growthrate!$F$3)^10 -> 1810434.1 | S14: =O14*(1+0.01*growthrate!$F$3)^10 -> 9717.7646
A15: 0199 | B15: 기타 비식용작물 | C15: 백만원 | D15: 505861 | E15: -15434 | F15: 490427 | G15: 195 | H15: =D15*(1+0.01*growthrate!E15)^2 -> 505861 | I15: =E15*(1+0.01*growthrate!$E$3)^2 -> -15900.493 | J15: =F15*(1+0.01*growthrate!$E$3)^2 -> 505250.16 | K15: =G15*(1+0.01*growthrate!$E$3)^2 -> 200.89387 | L15: =H15*(1+0.01*growthrate!$E$3)^5 -> 544955.96 | M15: =I15*(1+0.01*growthrate!$E$3)^5 -> -17129.346 | N15: =J15*(1+0.01*growthrate!$E$3)^5 -> 544297.91 | O15: =K15*(1+0.01*growthrate!$E$3)^5 -> 216.41976 | P15: =L15*(1+0.01*growthrate!$F$3)^10 -> 584327.22 | Q15: =M15*(1+0.01*growthrate!$F$3)^10 -> -18366.885 | R15: =N15*(1+0.01*growthrate!$F$3)^10 -> 583621.62 | S15: =O15*(1+0.01*growthrate!$F$3)^10 -> 232.05536
... A383: 9590 | B383: 중간투입계 | C383: 백만원 | D383: 784205547 | E383: 231751740 | F383: 1015957287 | G383: 784205547 | H383: =D383*(1+0.01*growthrate!E383)^2 -> 784205547 | I383: =E383*(1+0.01*growthrate!$E$3)^2 -> 2.3875644e+08 | J383: =F383*(1+0.01*growthrate!$E$3)^2 -> 1.0466646e+09 | K383: =G383*(1+0.01*growthrate!$E$3)^2 -> 8.0790816e+08 | L383: =H383*(1+0.01*growthrate!$E$3)^5 -> 8.4481209e+08 | M383: =I383*(1+0.01*growthrate!$E$3)^5 -> 2.5720849e+08 | N383: =J383*(1+0.01*growthrate!$E$3)^5 -> 1.127555e+09 | O383: =K383*(1+0.01*growthrate!$E$3)^5 -> 8.7034654e+08 | P383: =L383*(1+0.01*growthrate!$F$3)^10 -> 9.0584695e+08 | Q383: =M383*(1+0.01*growthrate!$F$3)^10 -> 2.7579095e+08 | R383: =N383*(1+0.01*growthrate!$F$3)^10 -> 1.2090171e+09 | S383: =O383*(1+0.01*growthrate!$F$3)^10 -> 9.3322617e+08

Sheet growthrate
A1: 시나리오 | B1: source | C1: unit | D1: 2023 | E1: 2025-2030 | F1: 2031-2040 | G1: 2041-2050
A2: 비관 | B2: KDI | C2: % | E2: 1.2 | F2: 0.4 | G2: -0.3
A3: 기준 | B3: KDI | C3: % | E3: 1.5 | F3: 0.7 | G3: 0.1
A4: 낙관 | B4: KDI | C4: % | E4: 1.7 | F4: 1.1 | G4: 0.5

Sheet producerprice
B1: 0111 | C1: 0112 | D1: 0113 | E1: 0114 | F1: 0121 | G1: 0122 | H1: 0191 | I1: 0192 | J1: 0193 | K1: 0194 | L1: 0195 | M1: 0196 | N1: 0199 | O1: 0211 | P1: 0212 | Q1: 0291 | R1: 0292 | S1: 0299 | T1: 0301 | U1: 0302 | V1: 0303 | W1: 0309 | X1: 0401 | Y1: 0402 | Z1: 0500 | AA1: 0611 | AB1: 0612 | AC1: 0621 | AD1: 0622 | AE1: 0711 | AF1: 0719 | AG1: 0721 | AH1: 0722 | AI1: 0729 | AJ1: 0811 | AK1: 0812 | AL1: 0813 | AM1: 0814 | AN1: 0821 | AO1: 0822 | AP1: 0831 | AQ1: 0832 | AR1: 0841 | AS1: 0842 | AT1: 0843 | AU1: 0851 | AV1: 0852 | AW1: 0861 | AX1: 0862 | AY1: 0871 | AZ1: 0872 | BA1: 0873 | BB1: 0879 | BC1: 0880 | BD1: 0911 | BE1: 0912 | BF1: 0913 | BG1: 0919 | BH1: 0920 | BI1: 1000 | BJ1: 1111 | BK1: 1119 | BL1: 1121 | BM1: 1122 | BN1: 1123 | BO1: 1130 | BP1: 1141 | BQ1: 1142 | BR1: 1149 | BS1: 1151 | BT1: 1152 | BU1: 1153 | BV1: 1154 | BW1: 1155 | BX1: 1201 | BY1: 1202 | BZ1: 1203 | CA1: 1204 | CB1: 1209 | CC1: 1311 | CD1: 1312 | CE1: 1313 | CF1: 1321 | CG1: 1322 | CH1: 1329 | CI1: 1410 | CJ1: 1421 | CK1: 1429 | CL1: 1431 | CM1: 1432 | CN1: 1433 | CO1: 1434 | CP1: 1439 | CQ1: 1500 | CR1: 1610 | CS1: 1621 | CT1: 1622 | CU1: 1623 | CV1: 1624 | CW1: 1625 | CX1: 1626 | CY1: 1627 | CZ1: 1628 | DA1: 1631 | DB1: 1639 | DC1: 1711 | DD1: 1712 | DE1: 1713 | DF1: 1719 | DG1: 1721 | DH1: 1722 | DI1: 1723 | DJ1: 1801 | DK1: 1802 | DL1: 1900 | DM1: 2000 | DN1: 2101 | DO1: 2102 | DP1: 2211 | DQ1: 2212 | DR1: 2221 | DS1: 2222 | DT1: 2291 | DU1: 2292 | DV1: 2299 | DW1: 2310 | DX1: 2391 | DY1: 2392 | DZ1: 2393 | EA1: 2399 | EB1: 2410 | EC1: 2491 | ED1: 2499 | EE1: 2501 | EF1: 2502 | EG1: 2503 | EH1: 2509 | EI1: 2611 | EJ1: 2612 | EK1: 2613 | EL1: 2614 | EM1: 2620 | EN1: 2631 | EO1: 2632 | EP1: 2691 | EQ1: 2692 | ER1: 2693 | ES1: 2694 | ET1: 2699 | EU1: 2711 | EV1: 2712 | EW1: 2713 | EX1: 2721 | EY1: 2722 | EZ1: 2723 | FA1: 2724 | FB1: 2725 | FC1: 2726 | FD1: 2727 | FE1: 2730 | FF1: 2791 | FG1: 2799 | FH1: 2811 | FI1: 2812 | FJ1: 2813 | FK1: 2814 | FL1: 2819 | FM1: 2821 | FN1: 2822 | FO1: 2829 | FP1: 2900 | FQ1: 3011 | FR1: 3012 | FS1: 3013 | FT1: 3014 | FU1: 3021 | FV1: 3022 | FW1: 3031 | FX1: 3032 | FY1: 3091 | FZ1: 3092 | GA1: 3093 | GB1: 3094 | GC1: 3095 | GD1: 3099 | GE1: 3101 | GF1: 3102 | GG1: 3201 | GH1: 3209 | GI1: 3310 | GJ1: 3391 | GK1: 3399 | GL1: 3401 | GM1: 3402 | GN1: 3409 | GO1: 3511 | GP1: 3512 | GQ1: 3519 | GR1: 3521 | GS1: 3522 | GT1: 3523 | GU1: 3611 | GV1: 3612 | GW1: 3613 | GX1: 3691 | GY1: 3692 | GZ1: 3710 | HA1: 3721 | HB1: 3722 | HC1: 3723 | HD1: 3724 | HE1: 3730 | HF1: 3740 | HG1: 3751 | HH1: 3752 | HI1: 3759 | HJ1: 3791 | HK1: 3792 | HL1: 3799 | HM1: 3810 | HN1: 3820 | HO1: 3831 | HP1: 3832 | HQ1: 3840 | HR1: 3851 | HS1: 3852 | HT1: 3891 | HU1: 3899 | HV1: 3911 | HW1: 3912 | HX1: 3920 | HY1: 3930 | HZ1: 3941 | IA1: 3942 | IB1: 3991 | IC1: 3992 | ID1: 3993 | IE1: 3994 | IF1: 3995 | IG1: 3999 | IH1: 4011 | II1: 4012 | IJ1: 4013 | IK1: 4014 | IL1: 4021 | IM1: 4022 | IN1: 4031 | IO1: 4032 | IP1: 4101 | IQ1: 4102 | IR1: 4103 | IS1: 4210 | IT1: 4220 | IU1: 4291 | IV1: 4299 | IW1: 4311 | IX1: 4312 | IY1: 4319 | IZ1: 4391 | JA1: 4392 | JB1: 4393 | JC1: 4394 | JD1: 4395 | JE1: 4396 | JF1: 4399 | JG1: 4401 | JH1: 4402 | JI1: 4501 | JJ1: 4502 | JK1: 4503 | JL1: 4504 | JM1: 4505 | JN1: 4506 | JO1: 4610 | JP1: 4620 | JQ1: 4700 | JR1: 4801 | JS1: 4802 | JT1: 4911 | JU1: 4912 | JV1: 4920 | JW1: 5010 | JX1: 5020 | JY1: 5030 | JZ1: 5111 | KA1: 5112 | KB1: 5113 | KC1: 5121 | KD1: 5122 | KE1: 5123 | KF1: 5124 | KG1: 5131 | KH1: 5132 | KI1: 5133 | KJ1: 5190 | KK1: 5200 | KL1: 5310 | KM1: 5321 | KN1: 5322 | KO1: 5401 | KP1: 5402 | KQ1: 5500 | KR1: 5611 | KS1: 5612 | KT1: 5613 | KU1: 5620 | KV1: 5630 | KW1: 5690 | KX1: 5710 | KY1: 5720 | KZ1: 5811 | LA1: 5812 | LB1: 5813 | LC1: 5814 | LD1: 5820 | LE1: 5911 | LF1: 5912 | LG1: 5991 | LH1: 5999 | LI1: 6001 | LJ1: 6002 | LK1: 6100 | LL1: 6211 | LM1: 6212 | LN1: 6290 | LO1: 6300 | LP1: 6401 | LQ1: 6402 | LR1: 6510 | LS1: 6591 | LT1: 6599 | LU1: 6601 | LV1: 6602 | LW1: 6603 | LX1: 6700 | LY1: 6800 | LZ1: 6911 | MA1: 6912 | MB1: 6920 | MC1: 7001 | MD1: 7002 | ME1: 7003 | MF1: 7004 | MG1: 7111 | MH1: 7112 | MI1: 7120 | MJ1: 7210 | MK1: 7291 | ML1: 7292 | MM1: 7299 | MN1: 7300 | MO1: 7410 | MP1: 7420 | MQ1: 7490 | MR1: 7511 | MS1: 7512 | MT1: 7520 | MU1: 7601 | MV1: 7602 | MW1: 7603 | MX1: 7701 | MY1: 7702 | MZ1: 7703 | NA1: 7801 | NB1: 7802 | NC1: 7901 | ND1: 7902 | NE1: 7903 | NF1: 7904 | NG1: 8001 | NH1: 8002 | NI1: 8101 | NJ1: 8109 | NK1: 8211 | NL1: 8212 | NM1: 8221 | NN1: 8222 | NO1: 8223 | NP1: 8229 | NQ1: 8300 | NR1: 9590
A2: 0111 | B2: 110358 | C2: 1952 | D2: 6084 | E2: 5141 | F2: 46111 | G2: 1700 | H2: 276 | I2: 93221 | J2: 671 | K2: 0 | L2: 5617 | M2: 51 | N2: 0 | O2: 42585 | P2: 210704 | Q2: 197493 | R2: 6693 | S2: 55174 | T2: 222 | U2: 0 | V2: 421 | W2: 1757 | X2: 0 | Y2: 0 | Z2: 26574 | AA2: 0 | AB2: 0 | AC2: 0 | AD2: 0 | AE2: 0 | AF2: 0 | AG2: 0 | AH2: 0 | AI2: 0 | AJ2: 0 | AK2: 0 | AL2: 0 | AM2: 0 | AN2: 0 | AO2: 0 | AP2: 6931049 | AQ2: 0 | AR2: 0 | AS2: 0 | AT2: 0 | AU2: 34 | AV2: 0 | AW2: 0 | AX2: 0 | AY2: 0 | AZ2: 0 | BA2: 607 | BB2: 2 | BC2: 279673 | BD2: 0 | BE2: 0 | BF2: 0 | BG2: 0 | BH2: 0 | BI2: 0 | BJ2: 0 | BK2: 0 | BL2: 0 | BM2: 0 | BN2: 0 | BO2: 0 | BP2: 0 | BQ2: 0 | BR2: 0 | BS2: 0 | BT2: 0 | BU2: 0 | BV2: 0 | BW2: 0 | BX2: 0 | BY2: 0 | BZ2: 0 | CA2: 0 | CB2: 0 | CC2: 0 | CD2: 0 | CE2: 0 | CF2: 0 | CG2: 0 | CH2: 0 | CI2: 0 | CJ2: 0 | CK2: 0 | CL2: 0 | CM2: 0 | CN2: 0 | CO2: 0 | CP2: 0 | CQ2: 0 | CR2: 0 | CS2: 0 | CT2: 0 | CU2: 0 | CV2: 0 | CW2: 0 | CX2: 0 | CY2: 0 | CZ2: 0 | DA2: 0 | DB2: 0 | DC2: 0 | DD2: 0 | DE2: 0 | DF2: 0 | DG2: 0 | DH2: 0 | DI2: 0 | DJ2: 0 | DK2: 0 | DL2: 0 | DM2: 87 | DN2: 0 | DO2: 0 | DP2: 0 | DQ2: 0 | DR2: 0 | DS2: 0 | DT2: 0 | DU2: 0 | DV2: 0 | DW2: 0 | DX2: 0 | DY2: 0 | DZ2: 0 | EA2: 0 | EB2: 0 | EC2: 0 | ED2: 0 | EE2: 0 | EF2: 0 | EG2: 0 | EH2: 0 | EI2: 0 | EJ2: 0 | EK2: 0 | EL2: 0 | EM2: 0 | EN2: 0 | EO2: 0 | EP2: 0 | EQ2: 0 | ER2: 0 | ES2: 0 | ET2: 0 | EU2: 0 | EV2: 0 | EW2: 0 | EX2: 0 | EY2: 0 | EZ2: 0 | FA2: 0 | FB2: 0 | FC2: 0 | FD2: 0 | FE2: 0 | FF2: 0 | FG2: 0 | FH2: 0 | FI2: 0 | FJ2: 0 | FK2: 0 | FL2: 0 | FM2: 0 | FN2: 0 | FO2: 0 | FP2: 0 | FQ2: 0 | FR2: 0 | FS2: 0 | FT2: 0 | FU2: 0 | FV2: 0 | FW2: 0 | FX2: 0 | FY2: 0 | FZ2: 0 | GA2: 0 | GB2: 0 | GC2: 0 | GD2: 0 | GE2: 0 | GF2: 0 | GG2: 0 | GH2: 0 | GI2: 0 | GJ2: 0 | GK2: 0 | GL2: 0 | GM2: 0 | GN2: 0 | GO2: 0 | GP2: 0 | GQ2: 0 | GR2: 0 | GS2: 0 | GT2: 0 | GU2: 0 | GV2: 0 | GW2: 0 | GX2: 0 | GY2: 0 | GZ2: 0 | HA2: 0 | HB2: 0 | HC2: 0 | HD2: 0 | HE2: 0 | HF2: 0 | HG2: 0 | HH2: 0 | HI2: 0 | HJ2: 0 | HK2: 0 | HL2: 0 | HM2: 0 | HN2: 0 | HO2: 0 | HP2: 0 | HQ2: 0 | HR2: 0 | HS2: 0 | HT2: 0 | HU2: 0 | HV2: 0 | HW2: 0 | HX2: 0 | HY2: 0 | HZ2: 0 | IA2: 0 | IB2: 0 | IC2: 0 | ID2: 0 | IE2: 0 | IF2: 0 | IG2: 0 | IH2: 0 | II2: 0 | IJ2: 0 | IK2: 0 | IL2: 0 | IM2: 0 | IN2: 0 | IO2: 0 | IP2: 0 | IQ2: 0 | IR2: 0 | IS2: 0 | IT2: 0 | IU2: 0 | IV2: 0 | IW2: 0 | IX2: 0 | IY2: 0 | IZ2: 0 | JA2: 0 | JB2: 0 | JC2: 0 | JD2: 0 | JE2: 881 | JF2: 412 | JG2: 321 | JH2: 0 | JI2: 0 | JJ2: 0 | JK2: 0 | JL2: 0 | JM2: 0 | JN2: 0 | JO2: 0 | JP2: 0 | JQ2: 0 | JR2: 0 | JS2: 0 | JT2: 0 | JU2: 0 | JV2: 0 | JW2: 0 | JX2: 0 | JY2: 0 | JZ2: 0 | KA2: 0 | KB2: 0 | KC2: 0 | KD2: 0 | KE2: 0 | KF2: 0 | KG2: 0 | KH2: 0 | KI2: 0 | KJ2: 0 | KK2: 2722 | KL2: 0 | KM2: 0 | KN2: 0 | KO2: 0 | KP2: 0 | KQ2: 0 | KR2: 0 | KS2: 0 | KT2: 0 | KU2: 0 | KV2: 0 | KW2: 0 | KX2: 0 | KY2: 0 | KZ2: 0 | LA2: 0 | LB2: 0 | LC2: 0 | LD2: 0 | LE2: 0 | LF2: 0 | LG2: 0 | LH2: 0 | LI2: 0 | LJ2: 0 | LK2: 0 | LL2: 0 | LM2: 0 | LN2: 0 | LO2: 0 | LP2: 0 | LQ2: 0 | LR2: 0 | LS2: 0 | LT2: 0 | LU2: 0 | LV2: 0 | LW2: 0 | LX2: 0 | LY2: 0 | LZ2: 0 | MA2: 0 | MB2: 0 | MC2: 0 | MD2: 0 | ME2: 0 | MF2: 0 | MG2: 0 | MH2: 0 | MI2: 0 | MJ2: 0 | MK2: 0 | ML2: 0 | MM2: 0 | MN2: 0 | MO2: 0 | MP2: 0 | MQ2: 0 | MR2: 2 | MS2: 216 | MT2: 0 | MU2: 0 | MV2: 0 | MW2: 0 | MX2: 0 | MY2: 0 | MZ2: 0 | NA2: 0 | NB2: 0 | NC2: 84 | ND2: 0 | NE2: 0 | NF2: 0 | NG2: 0 | NH2: 0 | NI2: 0 | NJ2: 0 | NK2: 0 | NL2: 0 | NM2: 0 | NN2: 0 | NO2: 0 | NP2: 0 | NQ2: 2 | NR2: 8028897
A3: 0112 | B3: 0 | C3: 2931 | D3: 0 | E3: 0 | F3: 0 | G3: 0 | H3: 0 | I3: 0 | J3: 0 | K3: 0 | L3: 0 | M3: 0 | N3: 0 | O3: 159 | P3: 2473 | Q3: 423 | R3: 412 | S3: 49 | T3: 0 | U3: 0 | V3: 0 | W3: 0 | X3: 0 | Y3: 0 | Z3: 0 | AA3: 0 | AB3: 0 | AC3: 0 | AD3: 0 | AE3: 0 | AF3: 0 | AG3: 0 | AH3: 0 | AI3: 0 | AJ3: 0 | AK3: 0 | AL3: 0 | AM3: 0 | AN3: 0 | AO3: 0 | AP3: 45948 | AQ3: 1544479 | AR3: 0 | AS3: 0 | AT3: 395514 | AU3: 12025 | AV3: 50678 | AW3: 114744 | AX3: 450957 | AY3: 587 | AZ3: 7142 | BA3: 57 | BB3: 204160 | BC3: 4066151 | BD3: 14120 | BE3: 0 | BF3: 76675 | BG3: 0 | BH3: 16 | BI3: 0 | BJ3: 0 | BK3: 0 | BL3: 0 | BM3: 0 | BN3: 0 | BO3: 0 | BP3: 0 | BQ3: 0 | BR3: 0 | BS3: 0 | BT3: 0 | BU3: 0 | BV3: 0 | BW3: 0 | BX3: 0 | BY3: 0 | BZ3: 0 | CA3: 0 | CB3: 0 | CC3: 0 | CD3: 0 | CE3: 0 | CF3: 0 | CG3: 0 | CH3: 0 | CI3: 0 | CJ3: 0 | CK3: 0 | CL3: 0 | CM3: 0 | CN3: 0 | CO3: 0 | CP3: 0 | CQ3: 0 | CR3: 0 | CS3: 0 | CT3: 0 | CU3: 0 | CV3: 0 | CW3: 0 | CX3: 0 | CY3: 0 | CZ3: 0 | DA3: 0 | DB3: 0 | DC3: 0 | DD3: 0 | DE3: 0 | DF3: 0 | DG3: 0 | DH3: 0 | DI3: 0 | DJ3: 0 | DK3: 0 | DL3: 0 | DM3: 0 | DN3: 0 | DO3: 0 | DP3: 0 | DQ3: 0 | DR3: 0 | DS3: 0 | DT3: 0 | DU3: 0 | DV3: 0 | DW3: 0 | DX3: 0 | DY3: 0 | DZ3: 0 | EA3: 0 | EB3: 0 | EC3: 0 | ED3: 0 | EE3: 0 | EF3: 0 | EG3: 0 | EH3: 0 | EI3: 0 | EJ3: 0 | EK3: 0 | EL3: 0 | EM3: 0 | EN3: 0 | EO3: 0 | EP3: 0 | EQ3: 0 | ER3: 0 | ES3: 0 | ET3: 0 | EU3: 0 | EV3: 0 | EW3: 0 | EX3: 0 | EY3: 0 | EZ3: 0 | FA3: 0 | FB3: 0 | FC3: 0 | FD3: 0 | FE3: 0 | FF3: 0 | FG3: 0 | FH3: 0 | FI3: 0 | FJ3: 0 | FK3: 0 | FL3: 0 | FM3: 0 | FN3: 0 | FO3: 0 | FP3: 0 | FQ3: 0 | FR3: 0 | FS3: 0 | FT3: 0 | FU3: 0 | FV3: 0 | FW3: 0 | FX3: 0 | FY3: 0 | FZ3: 0 | GA3: 0 | GB3: 0 | GC3: 0 | GD3: 0 | GE3: 0 | GF3: 0 | GG3: 0 | GH3: 0 | GI3: 0 | GJ3: 0 | GK3: 0 | GL3: 0 | GM3: 0 | GN3: 0 | GO3: 0 | GP3: 0 | GQ3: 0 | GR3: 0 | GS3: 0 | GT3: 0 | GU3: 0 | GV3: 0 | GW3: 0 | GX3: 0 | GY3: 0 | GZ3: 0 | HA3: 0 | HB3: 0 | HC3: 0 | HD3: 0 | HE3: 0 | HF3: 0 | HG3: 0 | HH3: 0 | HI3: 0 | HJ3: 0 | HK3: 0 | HL3: 0 | HM3: 0 | HN3: 0 | HO3: 0 | HP3: 0 | HQ3: 0 | HR3: 0 | HS3: 0 | HT3: 0 | HU3: 0 | HV3: 0 | HW3: 0 | HX3: 0 | HY3: 0 | HZ3: 0 | IA3: 0 | IB3: 0 | IC3: 0 | ID3: 0 | IE3: 0 | IF3: 0 | IG3: 0 | IH3: 0 | II3: 0 | IJ3: 0 | IK3: 0 | IL3: 0 | IM3: 0 | IN3: 0 | IO3: 0 | IP3: 0 | IQ3: 0 | IR3: 0 | IS3: 0 | IT3: 0 | IU3: 0 | IV3: 0 | IW3: 0 | IX3: 0 | IY3: 0 | IZ3: 0 | JA3: 0 | JB3: 0 | JC3: 0 | JD3: 0 | JE3: 70 | JF3: 66 | JG3: 42371 | JH3: 0 | JI3: 0 | JJ3: 0 | JK3: 0 | JL3: 0 | JM3: 0 | JN3: 0 | JO3: 0 | JP3: 0 | JQ3: 0 | JR3: 0 | JS3: 0 | JT3: 0 | JU3: 0 | JV3: 0 | JW3: 0 | JX3: 0 | JY3: 0 | JZ3: 0 | KA3: 0 | KB3: 0 | KC3: 0 | KD3: 0 | KE3: 0 | KF3: 0 | KG3: 0 | KH3: 0 | KI3: 0 | KJ3: 0 | KK3: 0 | KL3: 0 | KM3: 0 | KN3: 0 | KO3: 0 | KP3: 0 | KQ3: 0 | KR3: 0 | KS3: 0 | KT3: 0 | KU3: 0 | KV3: 0 | KW3: 0 | KX3: 0 | KY3: 0 | KZ3: 49530 | LA3: 1611 | LB3: 13 | LC3: 1343 | LD3: 0 | LE3: 0 | LF3: 0 | LG3: 0 | LH3: 0 | LI3: 0 | LJ3: 0 | LK3: 0 | LL3: 0 | LM3: 0 | LN3: 0 | LO3: 0 | LP3: 0 | LQ3: 0 | LR3: 0 | LS3: 0 | LT3: 0 | LU3: 0 | LV3: 0 | LW3: 0 | LX3: 0 | LY3: 0 | LZ3: 0 | MA3: 0 | MB3: 0 | MC3: 301 | MD3: 0 | ME3: 0 | MF3: 0 | MG3: 0 | MH3: 0 | MI3: 0 | MJ3: 0 | MK3: 0 | ML3: 0 | MM3: 0 | MN3: 0 | MO3: 0 | MP3: 0 | MQ3: 0 | MR3: 438 | MS3: 70 | MT3: 0 | MU3: 312 | MV3: 0 | MW3: 0 | MX3: 0 | MY3: 0 | MZ3: 0 | NA3: 0 | NB3: 3584 | NC3: 0 | ND3: 0 | NE3: 0 | NF3: 0 | NG3: 0 | NH3: 0 | NI3: 0 | NJ3: 0 | NK3: 0 | NL3: 0 | NM3: 0 | NN3: 0 | NO3: 0 | NP3: 0 | NQ3: 28 | NR3: 7089437
